Workbook

Sheet main sheet
A1: GEM location ID | B1: GEM unit ID | C1: Wiki URL | D1: Plant name | E1: Capacity (MW) | F1: Status | G1: Start year | H1: RUPTL 2025-RE Base_COD | I1: RUPTL 2025-ARED_COD | J1: tag year | K1: Latitude | L1: Longitude | M1: City | N1: State/Province | O1: Ownership | P1: Captive industry use | Q1: Captive industry type | R1: Fuel classification? | S1: Owner(s) | T1: Parent(s) | U1: Technology | V1: Thermal efficiency (%) | W1: APC technology | X1: Annual NOx, ton/year | Y1: Annual SOx, ton/year | Z1: Annual PMs, ton/year | AA1: Conc. Dust | AB1: Conc. NOx | AC1: Conc. CO | AD1: Conc. CO2 | AE1: Conc. SOx | AF1: Conc. PM | AG1: Unit for gases | AH1: Stack height (m) | AI1: Stack diameter (m) | AJ1: Flue exit temp (℃) | AK1: Flue velocity (m/s) | AL1: to be checked | AM1: GOGPT Jul 2025 | AN1: GOGPT internal sharing, Oct 2025 | AO1: TrendAsia internal sharing, Oct 2025
A2: L100000102774 | B2: G100001064105 | C2: https://www.gem.wiki/Jayapura-2_power_station | D2: Jayapura-2 power station | E2: 50 | F2: announced | G2: 2027 | K2: -2.60839 | L2: 140.80748 | M2: Jayapura | N2: Papua | O2: PLN | R2: Multi fuel | S2: PT PLN (Persero) [100%] | T2: PT PLN (Persero) [100.0%] | U2: ICCC | AN2: x
A3: L100000104578 | B3: G100001064106 | C3: https://www.gem.wiki/Jayapura-3_power_station | D3: Jayapura-3 power station | E3: 50 | F3: announced | G3: 2034 | K3: -2.60839 | L3: 140.80748 | M3: Jayapura | N3: Papua | O3: PLN | R3: Multi fuel | S3: PT PLN (Persero) [100%] | T3: PT PLN (Persero) [100.0%] | U3: ICCC | AN3: x
A4: L100000408072 | B4: G100001064205 | C4: https://www.gem.wiki/Jayapura_power_station | D4: Jayapura power station | E4: 50 | F4: announced | G4: 2026 | K4: -2.616361 | L4: 140.7893 | M4: Jayapura | N4: Papua | O4: PLN | R4: Gas only | S4: PT PLN (Persero) [100%] | T4: PT PLN (Persero) [100.0%] | U4: internal combustion | AN4: x
A5: L100000405950 | B5: G100000405936 | C5: https://www.gem.wiki/Sulbagut_1_Combined_Cycle_power_station | D5: Sulbagut 1 Combined Cycle power station | E5: 50 | F5: announced | G5: 2027 | K5: 1.657387 | L5: 125.08887 | N5: Sulawesi | O5: PLN | R5: Multi fuel | S5: PT PLN (Persero) | T5: PT PLN (Persero) | U5: Combined Cycle Gas Turbine (CCGT) | AN5: x
A6: L100001056429 | B6: G100001064470 | C6: https://www.gem.wiki/Sumbagut/Banda_Aceh_sewa_power_station | D6: Sumbagut/Banda Aceh sewa power station | E6: 50 | F6: announced | G6: 2026 | N6: Aceh | O6: PLN | AN6: x
A7: L100000405938 | B7: G100000405921 | C7: https://www.gem.wiki/Kalsel_1_power_station | D7: Kalsel 1 power station | E7: 100 | F7: announced | G7: 2027 | K7: -2.737592 | L7: 114.73802 | M7: not found | N7: South Kalimantan | O7: PLN | R7: Multi fuel | S7: PT PLN (Persero) [100%] | T7: PT PLN (Persero) [100.0%] | U7: Combined Cycle Gas Turbine (CCGT) | AM7: x
A8: L100000405280 | B8: G100000404273 | C8: https://www.gem.wiki/Krakatau_power_station | D8: Krakatau power station | E8: 120 | F8: announced | G8: not found | K8: -5.9924 | L8: 105.9849 | M8: Samangraya | N8: Banten | O8: Captive | R8: Gas only | S8: PT Krakatau Daya Listrik [100%] | T8: PT Krakatau Steel (Persero) Tbk [100.0%] | U8: Combined Cycle Gas Turbine (CCGT) | AM8: x
A9: L100000405292 | B9: G100000404303 | C9: https://www.gem.wiki/Sumbagut_Gas_and_Steam_power_station | D9: Sumbagut Gas and Steam power station | E9: 200 | F9: announced | G9: 2030 | K9: 3.760031 | L9: 98.745965 | M9: Medan | N9: North Sumatra | O9: PLN | R9: Gas only | S9: PT PLN Nusantara Power [100%] | T9: PT PLN (Persero) [100.0%] | U9: Combined Cycle Gas Turbine (CCGT) | AM9: x
A10: L100000102724 | B10: G100000404307 | C10: https://www.gem.wiki/Madura_PTBA_power_station | D10: Madura PTBA power station | E10: 300 | F10: announced | G10: 2025 | K10: -7.077733 | L10: 113.28709 | M10: Pulau Madura | N10: East Java | O10: PLN | R10: Gas only | S10: PT PLN (Persero) [100%] | T10: PT PLN (Persero) [100.0%] | U10: Combined Cycle Gas Turbine (CCGT) | AM10: x
A11: L100000405292 | B11: G100000404304 | C11: https://www.gem.wiki/Sumbagut_Gas_and_Steam_power_station | D11: Sumbagut Gas and Steam power station | E11: 300 | F11: announced | G11: 2030 | K11: 3.760031 | L11: 98.745965 | M11: Medan | N11: North Sumatra | O11: PLN | R11: Gas only | S11: PT PLN Nusantara Power [100%] | T11: PT PLN (Persero) [100.0%] | U11: Combined Cycle Gas Turbine (CCGT) | AM11: x
A12: L100000405292 | B12: G100000404305 | C12: https://www.gem.wiki/Sumbagut_Gas_and_Steam_power_station | D12: Sumbagut Gas and Steam power station | E12: 300 | F12: announced | G12: 2030 | K12: 3.760031 | L12: 98.745965 | M12: Medan | N12: North Sumatra | O12: PLN | R12: Gas only | S12: PT PLN Nusantara Power [100%] | T12: PT PLN (Persero) [100.0%] | U12: Combined Cycle Gas Turbine (CCGT) | AM12: x
A13: L100000406379 | B13: G100000406288 | C13: https://www.gem.wiki/Batubara_power_station | D13: Batubara power station | E13: 800 | F13: announced | G13: not found | K13: 3.285553 | L13: 99.508176 | M13: Perupuk | N13: North Sumatra | O13: Captive | R13: Gas only | S13: PT Hanlim Power Corp [100%] | T13: Hanlim Power Corp [100.0%] | U13: Combined Cycle Gas Turbine (CCGT) | AM13: x
A14: L100000405937 | B14: G100000405919 | C14: https://www.gem.wiki/Jawa-3_Combined_Cycle_power_station | D14: Jawa-3 Combined Cycle power station | E14: 800 | F14: announced | G14: 2027 | K14: -7.109509 | L14: 112.62168 | M14: not found | N14: East Java | O14: PLN | R14: Gas only | S14: PT PLN Nusantara Power [100%] | T14: PT PLN (Persero) [100.0%] | U14: Combined Cycle Gas Turbine (CCGT) | AM14: x
D15: Kalbar Sewa | E15: -55 | F15: announced (RUPTL 2025-2034) | G15: =H15 -> 2028 | H15: 2028 | J15: 2025-2029 | K15: =vlookup(D15,'upcoming, not in GEM'!A:D,3,false) -> 0 | L15: =vlookup(D15,'upcoming, not in GEM'!A:D,4,false) -> 111 | N15: =vlookup(D15,'upcoming, not in GEM'!A:B,2,false) -> West Kalimantan | O15: PLN | AL15: x
D16: Kalbar Sewa | E16: -50 | F16: announced (RUPTL 2025-2034) | G16: =H16 -> 2027 | H16: 2027 | J16: 2025-2029 | K16: =vlookup(D16,'upcoming, not in GEM'!A:D,3,false) -> 0 | L16: =vlookup(D16,'upcoming, not in GEM'!A:D,4,false) -> 111 | N16: =vlookup(D16,'upcoming, not in GEM'!A:B,2,false) -> West Kalimantan | O16: PLN | AL16: x
D17: Kalbar Sewa | E17: -50 | F17: announced (RUPTL 2025-2034) | G17: =I17 -> 2028 | I17: 2028 | J17: 2025-2029 | K17: =vlookup(D17,'upcoming, not in GEM'!A:D,3,false) -> 0 | L17: =vlookup(D17,'upcoming, not in GEM'!A:D,4,false) -> 111 | N17: =vlookup(D17,'upcoming, not in GEM'!A:B,2,false) -> West Kalimantan | O17: PLN | AL17: x
D18: Kalbar Sewa | E18: -35 | F18: announced (RUPTL 2025-2034) | G18: =I18 -> 2029 | I18: 2029 | J18: 2025-2029 | K18: =vlookup(D18,'upcoming, not in GEM'!A:D,3,false) -> 0 | L18: =vlookup(D18,'upcoming, not in GEM'!A:D,4,false) -> 111 | N18: =vlookup(D18,'upcoming, not in GEM'!A:B,2,false) -> West Kalimantan | O18: PLN | AL18: x
D19: Kalbar Sewa | E19: -20 | F19: announced (RUPTL 2025-2034) | G19: =I19 -> 2027 | I19: 2027 | J19: 2025-2029 | K19: =vlookup(D19,'upcoming, not in GEM'!A:D,3,false) -> 0 | L19: =vlookup(D19,'upcoming, not in GEM'!A:D,4,false) -> 111 | N19: =vlookup(D19,'upcoming, not in GEM'!A:B,2,false) -> West Kalimantan | O19: PLN | AL19: x
D20: Tobelo | E20: 10 | F20: announced (RUPTL 2025-2034) | G20: =I20 -> 2025 | H20: 2025 | I20: 2025 | J20: 2025-2029 | K20: =vlookup(D20,'upcoming, not in GEM'!A:D,3,false) -> 1.5 | L20: =vlookup(D20,'upcoming, not in GEM'!A:D,4,false) -> 127.8 | N20: =vlookup(D20,'upcoming, not in GEM'!A:B,2,false) -> North Maluku (Halmahera Island) | O20: PLN | AL20: x
D21: Sofifi | E21: 10 | F21: announced (RUPTL 2025-2034) | G21: =I21 -> 2026 | H21: 2026 | I21: 2026 | J21: 2025-2029 | K21: =vlookup(D21,'upcoming, not in GEM'!A:D,3,false) -> 0.7 | L21: =vlookup(D21,'upcoming, not in GEM'!A:D,4,false) -> 127.5 | N21: =vlookup(D21,'upcoming, not in GEM'!A:B,2,false) -> North Maluku | O21: PLN | AL21: x
D22: Merauke 4 | E22: 10 | F22: announced (RUPTL 2025-2034) | G22: =I22 -> 2027 | H22: 2027 | I22: 2027 | J22: 2025-2029 | K22: =vlookup(D22,'upcoming, not in GEM'!A:D,3,false) -> -6.7 | L22: =vlookup(D22,'upcoming, not in GEM'!A:D,4,false) -> 140.4 | N22: =vlookup(D22,'upcoming, not in GEM'!A:B,2,false) -> South Papua (Papua Island) | O22: PLN | AL22: x
D23: Nabire 3 | E23: 10 | F23: announced (RUPTL 2025-2034) | G23: =I23 -> 2030 | H23: 2030 | I23: 2030 | J23: 2030-2034 | K23: =vlookup(D23,'upcoming, not in GEM'!A:D,3,false) -> -3.5 | L23: =vlookup(D23,'upcoming, not in GEM'!A:D,4,false) -> 135.5 | N23: =vlookup(D23,'upcoming, not in GEM'!A:B,2,false) -> Central Papua (Papua Island) | O23: PLN | AL23: x
D24: Baubau 2 | E24: 15 | F24: announced (RUPTL 2025-2034) | G24: =I24 -> 2026 | H24: 2026 | I24: 2026 | J24: 2025-2029 | K24: -5.459424 | L24: 122.60595 | N24: =vlookup(D24,'upcoming, not in GEM'!A:B,2,false) -> Southeast Sulawesi | O24: PLN | AL24: x
D25: Baubau 2 | E25: 15 | F25: announced (RUPTL 2025-2034) | G25: =I25 -> 2027 | H25: 2027 | I25: 2027 | J25: 2025-2029 | K25: -5.459424 | L25: 122.60595 | N25: =vlookup(D25,'upcoming, not in GEM'!A:B,2,false) -> Southeast Sulawesi | O25: PLN | AL25: x
D26: Tobelo 2 | E26: 20 | F26: announced (RUPTL 2025-2034) | G26: =I26 -> 2025 | H26: 2025 | I26: 2025 | J26: 2025-2029 | K26: =vlookup(D26,'upcoming, not in GEM'!A:D,3,false) -> 1.5 | L26: =vlookup(D26,'upcoming, not in GEM'!A:D,4,false) -> 127.8 | N26: =vlookup(D26,'upcoming, not in GEM'!A:B,2,false) -> North Maluku (Halmahera Island) | O26: PLN | AL26: x
D27: MPP Manokwari | E27: 20 | F27: announced (RUPTL 2025-2034) | G27: =I27 -> 2025 | H27: 2025 | I27: 2025 | J27: 2025-2029 | K27: =vlookup(D27,'upcoming, not in GEM'!A:D,3,false) -> -0.8 | L27: =vlookup(D27,'upcoming, not in GEM'!A:D,4,false) -> 134 | N27: =vlookup(D27,'upcoming, not in GEM'!A:B,2,false) -> West Papua | O27: PLN | AL27: x
D28: IPP Sorong | E28: 20 | F28: announced (RUPTL 2025-2034) | G28: =I28 -> 2026 | H28: 2026 | I28: 2026 | J28: 2025-2029 | K28: -0.866667 | L28: 131.25 | N28: =vlookup(D28,'upcoming, not in GEM'!A:B,2,false) -> West Papua | O28: IPP | AL28: x
D29: Manokwari 3 | E29: 20 | F29: announced (RUPTL 2025-2034) | G29: =I29 -> 2026 | H29: 2026 | I29: 2026 | J29: 2025-2029 | K29: =vlookup(D29,'upcoming, not in GEM'!A:D,3,false) -> -0.8 | L29: =vlookup(D29,'upcoming, not in GEM'!A:D,4,false) -> 134 | N29: =vlookup(D29,'upcoming, not in GEM'!A:B,2,false) -> West Papua | O29: PLN | AL29: x
D30: Halmahera 1 | E30: 20 | F30: announced (RUPTL 2025-2034) | G30: =I30 -> 2027 | H30: 2027 | I30: 2027 | J30: 2025-2029 | K30: -1.5614331 | L30: 127.42103 | N30: =vlookup(D30,'upcoming, not in GEM'!A:B,2,false) -> North Maluku (Halmahera Island) | O30: PLN | AL30: x
D31: Manokwari 4 | E31: 20 | F31: announced (RUPTL 2025-2034) | G31: =I31 -> 2031 | H31: 2031 | I31: 2031 | J31: 2030-2034 | K31: =vlookup(D31,'upcoming, not in GEM'!A:D,3,false) -> -0.8 | L31: =vlookup(D31,'upcoming, not in GEM'!A:D,4,false) -> 134 | N31: =vlookup(D31,'upcoming, not in GEM'!A:B,2,false) -> West Papua | O31: PLN | AL31: x
D32: Subagteng | E32: 25 | F32: announced (RUPTL 2025-2034) | G32: =I32 -> 2028 | H32: 2028 | I32: 2028 | J32: 2025-2029 | K32: =vlookup(D32,'upcoming, not in GEM'!A:D,3,false) -> -0.609017 | L32: =vlookup(D32,'upcoming, not in GEM'!A:D,4,false) -> 100.7537 | N32: =vlookup(D32,'upcoming, not in GEM'!A:B,2,false) -> South and Central Sumatra or Sulawesi | O32: IPP | AL32: x
D33: Madura 3 | E33: 30 | F33: announced (RUPTL 2025-2034) | G33: =I33 -> 2025 | H33: 2025 | I33: 2025 | J33: 2025-2029 | K33: =vlookup(D33,'upcoming, not in GEM'!A:D,3,false) -> -7 | L33: =vlookup(D33,'upcoming, not in GEM'!A:D,4,false) -> 113.3 | N33: =vlookup(D33,'upcoming, not in GEM'!A:B,2,false) -> East Java (Madura Island) | O33: PLN | AL33: x
D34: MPP Sambelia | E34: 30 | F34: announced (RUPTL 2025-2034) | G34: =I34 -> 2026 | H34: 2026 | I34: 2026 | J34: 2025-2029 | K34: =vlookup(D34,'upcoming, not in GEM'!A:D,3,false) -> -8.5 | L34: =vlookup(D34,'upcoming, not in GEM'!A:D,4,false) -> 116.3 | N34: =vlookup(D34,'upcoming, not in GEM'!A:B,2,false) -> West Nusa Tenggara (Lombok Island) | O34: PLN | AL34: x
D35: Kupang 2 | E35: 30 | F35: announced (RUPTL 2025-2034) | G35: =I35 -> 2027 | H35: 2027 | I35: 2027 | J35: 2025-2029 | K35: =vlookup(D35,'upcoming, not in GEM'!A:D,3,false) -> -10 | L35: =vlookup(D35,'upcoming, not in GEM'!A:D,4,false) -> 123.5 | N35: =vlookup(D35,'upcoming, not in GEM'!A:B,2,false) -> East Nusa Tenggara (Timor Island) | O35: PLN | AL35: x
D36: Kupang 2 | E36: 30 | F36: announced (RUPTL 2025-2034) | G36: =I36 -> 2028 | I36: 2028 | J36: 2025-2029 | K36: =vlookup(D36,'upcoming, not in GEM'!A:D,3,false) -> -10 | L36: =vlookup(D36,'upcoming, not in GEM'!A:D,4,false) -> 123.5 | N36: =vlookup(D36,'upcoming, not in GEM'!A:B,2,false) -> East Nusa Tenggara (Timor Island) | O36: PLN | AL36: x
D37: Luwuk | E37: 40 | F37: announced (RUPTL 2025-2034) | G37: =I37 -> 2025 | H37: 2025 | I37: 2025 | J37: 2025-2029 | K37: =vlookup(D37,'upcoming, not in GEM'!A:D,3,false) -> -1 | L37: =vlookup(D37,'upcoming, not in GEM'!A:D,4,false) -> 122.8 | N37: =vlookup(D37,'upcoming, not in GEM'!A:B,2,false) -> Central Sulawesi | O37: PLN | AL37: x
D38: Ambon 2 | E38: 50 | F38: announced (RUPTL 2025-2034) | G38: =H38 -> 2025 | H38: 2025 | I38: 2025 | J38: 2025-2029 | K38: -3.705 | L38: 128.17 | N38: =vlookup(D38,'upcoming, not in GEM'!A:B,2,false) -> Maluku (Ambon Island) | O38: PLN | AL38: x
D39: Tarakan | E39: 50 | F39: announced (RUPTL 2025-2034) | G39: =H39 -> 2027 | H39: 2027 | J39: 2025-2029 | K39: =vlookup(D39,'upcoming, not in GEM'!A:D,3,false) -> 3.3 | L39: =vlookup(D39,'upcoming, not in GEM'!A:D,4,false) -> 117.6 | N39: =vlookup(D39,'upcoming, not in GEM'!A:B,2,false) -> North Kalimantan (Tarakan Island) | O39: PLN | AL39: x
A40: L100001056427 | B40: G100001064468 | C40: https://www.gem.wiki/Minahasa_power_station | D40: Minahasa | E40: 50 | F40: announced (RUPTL 2025-2034) | G40: =I40 -> 2027 | H40: 2027 | I40: 2027 | J40: 2025-2029 | K40: =vlookup(D40,'upcoming, not in GEM'!A:D,3,false) -> 1 | L40: =vlookup(D40,'upcoming, not in GEM'!A:D,4,false) -> 124.8 | N40: =vlookup(D40,'upcoming, not in GEM'!A:B,2,false) -> North Sulawesi | O40: PLN | R40: Gas only | S40: PT PLN (Persero) | T40: PT PLN (Persero) | U40: Open Cycle Gas Turbine (OCGT) | AL40: x | AN40: x
...

Sheet upcoming, not in GEM
A1: Power Plant Listing | B1: Province | C1: Latitude | D1: Longitude
A2: Jawa-4 | B2: West Java | C2: -6.7 | D2: 107.5
A3: Jawa-5 | B3: West Java | C3: -6.7 | D3: 107.5
A4: Jawa-6 | B4: West Java | C4: -6.7 | D4: 107.5
A5: Sulbagsel | B5: South Sulawesi and West Sulawesi | C5: -3.5 | D5: 120
A6: Sulbagsel | B6: South Sulawesi and West Sulawesi | C6: -3.5 | D6: 120
A7: Sulbagsel 3 | B7: South Sulawesi and West Sulawesi | C7: -3.5 | D7: 120
A8: Jawa-Bali-7 | B8: Java or Bali | C8: -6.7 | D8: 107.5
A9: Sulbagsel | B9: South Sulawesi and West Sulawesi | C9: -3.5 | D9: 120
A10: Jawa-Bali-2 | B10: Java or Bali | C10: -6.7 | D10: 107.5
A11: Jawa-Bali-3 | B11: Java or Bali | C11: -6.7 | D11: 107.5
A12: Jawa-Bali-6 | B12: Java or Bali | C12: -6.7 | D12: 107.5
A13: Jawa-Bali-4 | B13: Java or Bali | C13: -6.7 | D13: 107.5
... A77: Nabire 3 | B77: Central Papua (Papua Island) | C77: -3.5 | D77: 135.5

Sheet not in the pipeline
A1: GEM location ID | B1: GEM unit ID | C1: Wiki URL | D1: Plant name | E1: Capacity (MW) | F1: Status | G1: Start year | H1: Latitude | I1: Longitude | J1: City | K1: State/Province | L1: Ownership | M1: Captive industry use | N1: Captive industry type | O1: Fuel classification? | P1: Owner(s) | Q1: Parent(s)
A2: L100000405265 | B2: G100000405915 | C2: https://www.gem.wiki/Belawan_power_station | D2: Belawan power station | E2: 430 | F2: cancelled | H2: 3.773148 | I2: 98.670029 | J2: Belawan | K2: North Sumatra | O2: LNG only | P2: =vlookup(B2,'GEM GOGPT_Aug 2025'!B:AB,25,false) -> PT PLN (Persero) [100%] | Q2: =vlookup(B2,'GEM GOGPT_Aug 2025'!B:AB,27,false) -> PT PLN (Persero) [100.0%]
A3: L100000405941 | B3: G100000405927 | C3: https://www.gem.wiki/Lampung_Peaker_power_station | D3: Lampung Peaker power station | E3: 200 | F3: cancelled | H3: -5.568576 | I3: 105.37802 | J3: not found | K3: Sumatra | O3: LNG only | P3: =vlookup(B3,'GEM GOGPT_Aug 2025'!B:AB,25,false) -> PT PLN (Persero) [100%] | Q3: =vlookup(B3,'GEM GOGPT_Aug 2025'!B:AB,27,false) -> PT PLN (Persero) [100.0%]
A4: L100000405290 | B4: G100000400927 | C4: https://www.gem.wiki/Soekarno-Hatta_Airport_power_station | D4: Soekarno-Hatta Airport power station | E4: 60 | F4: cancelled | H4: -6.127523 | I4: 106.65152 | J4: Tangerang | K4: Banten | O4: Gas only | P4: =vlookup(B4,'GEM GOGPT_Aug 2025'!B:AB,25,false) -> PT Angkasa Pura Indonesia [100%] | Q4: =vlookup(B4,'GEM GOGPT_Aug 2025'!B:AB,27,false) -> PT Aviasi Wisata Indonesia (Persero)
A5: L100000405263 | B5: G100000400917 | C5: https://www.gem.wiki/Bantaeng_LNG_power_station | D5: Bantaeng LNG power station | E5: 600 | F5: cancelled - inferred 4 y | H5: -5.471156 | I5: 119.83763 | J5: Bantaeng | K5: South Sulawesi | O5: LNG only | P5: =vlookup(B5,'GEM GOGPT_Aug 2025'!B:AB,25,false) -> PT Energi Nusantara Merah Putih [100%] | Q5: =vlookup(B5,'GEM GOGPT_Aug 2025'!B:AB,27,false) -> PT Energi Nusantara Merah Putih [100.0%]
A6: L100000406379 | B6: G100000406291 | C6: https://www.gem.wiki/Batubara_power_station | D6: Batubara power station | E6: 800 | F6: cancelled - inferred 4 y | H6: 3.285553 | I6: 99.508176 | J6: Perupuk | K6: North Sumatra | O6: Gas only | P6: =vlookup(B6,'GEM GOGPT_Aug 2025'!B:AB,25,false) -> PT Hanlim Power Corp [100%] | Q6: =vlookup(B6,'GEM GOGPT_Aug 2025'!B:AB,27,false) -> Hanlim Power Corp [100.0%]
A7: L100000406379 | B7: G100000406290 | C7: https://www.gem.wiki/Batubara_power_station | D7: Batubara power station | E7: 800 | F7: cancelled - inferred 4 y | H7: 3.285553 | I7: 99.508176 | J7: Perupuk | K7: North Sumatra | O7: Gas only | P7: =vlookup(B7,'GEM GOGPT_Aug 2025'!B:AB,25,false) -> PT Hanlim Power Corp [100%] | Q7: =vlookup(B7,'GEM GOGPT_Aug 2025'!B:AB,27,false) -> Hanlim Power Corp [100.0%]
A8: L100000406379 | B8: G100000406289 | C8: https://www.gem.wiki/Batubara_power_station | D8: Batubara power station | E8: 800 | F8: cancelled - inferred 4 y | H8: 3.285553 | I8: 99.508176 | J8: Perupuk | K8: North Sumatra | O8: Gas only | P8: =vlookup(B8,'GEM GOGPT_Aug 2025'!B:AB,25,false) -> PT Hanlim Power Corp [100%] | Q8: =vlookup(B8,'GEM GOGPT_Aug 2025'!B:AB,27,false) -> Hanlim Power Corp [100.0%]
A9: L100000405287 | B9: G100000404264 | C9: https://www.gem.wiki/Perak_power_station | D9: Perak power station | E9: 400 | F9: cancelled - inferred 4 y | H9: -7.209975 | I9: 112.72389 | J9: Surabaya City | K9: East Java | O9: Gas only | P9: =vlookup(B9,'GEM GOGPT_Aug 2025'!B:AB,25,false) -> PT PLN Indonesia Power [100%] | Q9: =vlookup(B9,'GEM GOGPT_Aug 2025'!B:AB,27,false) -> PT PLN (Persero) [100.0%]
A10: L100000405278 | B10: G100000404253 | C10: https://www.gem.wiki/Keramasan_Asta_power_station | D10: Keramasan Asta power station | E10: 145 | F10: mothballed | G10: 2010 | H10: -3.030261 | I10: 104.74198 | J10: Keramasan | K10: Sumatra | O10: Gas only | P10: =vlookup(B10,'GEM GOGPT_Aug 2025'!B:AB,25,false) -> PT Asta Keramasan Energi [100%] | Q10: =vlookup(B10,'GEM GOGPT_Aug 2025'!B:AB,27,false) -> PT Leyand International Tbk [100.0%]
A11: L100000405943 | B11: G100000405929 | C11: https://www.gem.wiki/Luwuk_power_station | D11: Luwuk power station | E11: 150 | F11: shelved | G11: 2021 | H11: -1.325641 | I11: 122.49828 | J11: Nonong | K11: Central Sulawesi | O11: Gas only | P11: =vlookup(B11,'GEM GOGPT_Aug 2025'!B:AB,25,false) -> PT PLN (Persero) [100%] | Q11: =vlookup(B11,'GEM GOGPT_Aug 2025'!B:AB,27,false) -> PT PLN (Persero) [100.0%]
A12: L100000405948 | B12: G100000405934 | C12: https://www.gem.wiki/Riau_2_power_station | D12: Riau 2 power station | E12: 250 | F12: shelved | G12: 2024 | H12: 1.63916 | I12: 101.60876 | J12: not found | K12: Riau | O12: Gas only | P12: =vlookup(B12,'GEM GOGPT_Aug 2025'!B:AB,25,false)
A13: L100000405950 | B13: G100000405936 | C13: https://www.gem.wiki/Sulbagut_1_Combined_Cycle_power_station | D13: Sulbagut 1 Combined Cycle power station | E13: 150 | F13: shelved | H13: 1.657387 | I13: 125.08887 | J13: not found | K13: North Sulawesi | O13: Multi fuel | P13: =vlookup(B13,'GEM GOGPT_Aug 2025'!B:AB,25,false) -> PT PLN (Persero) [100%]
A14: L100000405951 | B14: G100000405937 | C14: https://www.gem.wiki/Sulsel_power_station | D14: Sulsel power station | E14: 450 | F14: shelved | H14: -4.935711 | I14: 119.52311 | J14: not found | K14: South Sulawesi | O14: Gas only | P14: =vlookup(B14,'GEM GOGPT_Aug 2025'!B:AB,25,false) -> PT PLN (Persero) [100%]
A15: L100000405264 | B15: G100000404256 | C15: https://www.gem.wiki/Bekasi_power_station | D15: Bekasi power station | E15: 130 | F15: shelved - inferred 2 y | H15: -6.269558 | I15: 107.15968 | J15: Cikarang | K15: West Java | O15: Gas only | P15: =vlookup(B15,'GEM GOGPT_Aug 2025'!B:AB,25,false) -> PT Bekasi Power [100%]
A16: L100000408314 | B16: G100000411718 | C16: https://www.gem.wiki/Sujiawumei_LNG_power_station | D16: Sujiawumei LNG power station | E16: 800 | F16: shelved - inferred 2 y | H16: -7.035171 | I16: 106.54915 | K16: West Java | O16: LNG only | P16: =vlookup(B16,'GEM GOGPT_Aug 2025'!B:AB,25,false) -> Royal Maha Indonesia
A17: L100000408314 | B17: G100000411717 | C17: https://www.gem.wiki/Sujiawumei_LNG_power_station | D17: Sujiawumei LNG power station | E17: 800 | F17: shelved - inferred 2 y | H17: -7.035171 | I17: 106.54915 | K17: West Java | O17: LNG only | P17: =vlookup(B17,'GEM GOGPT_Aug 2025'!B:AB,25,false) -> Royal Maha Indonesia
A18: L100000408314 | B18: G100000411716 | C18: https://www.gem.wiki/Sujiawumei_LNG_power_station | D18: Sujiawumei LNG power station | E18: 800 | F18: shelved - inferred 2 y | H18: -7.035171 | I18: 106.54915 | K18: West Java | O18: LNG only | P18: =vlookup(B18,'GEM GOGPT_Aug 2025'!B:AB,25,false) -> Royal Maha Indonesia

Sheet GEM GOGPT_Aug 2025
A1: GEM location ID | B1: GEM unit ID | C1: Wiki URL | D1: Country/Area | E1: Plant name | F1: Plant Name in Local Language / Script | G1: Other Name(s) | H1: Unit name | I1: Fuel | J1: Capacity (MW) | K1: Status | L1: Turbine/Engine Technology | M1: Equipment Manufacturer/Model | N1: CHP | O1: Hydrogen capable? | P1: CCS attachment? | Q1: Conversion/replacement? | R1: Conversion from/replacement of (fuel) | S1: Conversion from/replacement of (GEM unit ID) | T1: Conversion to (fuel) | U1: Conversion to (GEM unit ID) | V1: Start year | W1: Retired year | X1: Planned retire | Y1: Operator(s) | Z1: Owner(s) | AA1: Owner GEM Entity ID | AB1: Parent(s) | AC1: Parent GEM Entity ID | AD1: Latitude | AE1: Longitude | AF1: Location accuracy | AG1: City | AH1: Local area (taluk, county) | AI1: Major area (prefecture, district) | AJ1: State/Province | AK1: Subregion | AL1: Region | AM1: Other IDs (location) | AN1: Other IDs (unit) | AO1: Captive industry use | AP1: Captive industry type | AQ1: Captive non-industry use | AR1: Fuel classification?
A2: L100000102773 | B2: G100001018115 | C2: https://www.gem.wiki/Amamapare_Port_power_station | D2: Indonesia | E2: Amamapare Port power station | H2: CC1 | I2: fossil gas: LNG | J2: 265 | K2: pre-construction | L2: combined cycle | M2: not found | Q2: replacement | R2: coal: unknown, coal: unknown, coal: unknown | S2: G100000100142, G100000100143, G100000100144 | V2: 2027 | Z2: PT Puncakjaya Power [100%] | AA2: E100000121062 [100%] | AB2: PT Puncakjaya Power [100.0%] | AC2: E100000121062 [100.0%] | AD2: -4.827752 | AE2: 136.83908 | AF2: exact | AG2: Amamapare | AH2: Mimika Timur Jauh | AI2: Mimika | AJ2: Papua | AK2: South-eastern Asia | AL2: Asia | AO2: power | AP2: other metals & mining | AR2: LNG only
A3: L100000408062 | B3: G100000411330 | C3: https://www.gem.wiki/Arun_I_power_station | D3: Indonesia | E3: Arun I power station | H3: 1 | I3: fossil gas: LNG | J3: 184.3 | K3: operating | L3: internal combustion | N3: not found | P3: not found | V3: 2015 | Z3: PT PLN (Persero) [100%] | AA3: E100000000537 [100%] | AB3: PT PLN (Persero) [100.0%] | AC3: E100000000537 [100.0%] | AD3: 5.215648 | AE3: 97.090454 | AF3: exact | AG3: Lhokseumawe | AJ3: Aceh | AK3: South-eastern Asia | AL3: Asia | AR3: LNG only
A4: L100000408061 | B4: G100000411329 | C4: https://www.gem.wiki/Arun_II_power_station | D4: Indonesia | E4: Arun II power station | G4: PLTMG Sumbagut 2 | H4: 2 | I4: fossil gas: natural gas | J4: 240.5 | K4: operating | L4: internal combustion | N4: not found | P4: not found | V4: 2021 | Z4: PT PLN (Persero) [100%] | AA4: E100000000537 [100%] | AB4: PT PLN (Persero) [100.0%] | AC4: E100000000537 [100.0%] | AD4: 5.214774 | AE4: 97.085577 | AF4: exact | AG4: Lhokseumawe | AJ4: Aceh | AK4: South-eastern Asia | AL4: Asia | AR4: Gas only
A5: L100000408313 | B5: G100000411719 | C5: https://www.gem.wiki/Bahodopi_Vale_Nickel_Smelter_power_station | D5: Indonesia | E5: Bahodopi Vale Nickel Smelter power station | H5: 1 | I5: fossil gas: LNG | J5: 500 | K5: pre-construction | L5: unknown | N5: not found | V5: 2026 | Z5: PT Vale Indonesia Tbk [100%] | AA5: E100001010523 [100%] | AB5: PT Vale Indonesia Tbk [100.0%] | AC5: E100001010523 [100.0%] | AD5: -2.7809 | AE5: 121.82373 | AF5: approximate | AG5: Bahomotefe | AJ5: Sulawesi | AK5: South-eastern Asia | AL5: Asia | AO5: power | AP5: other metals & mining | AR5: LNG only
A6: L100000407608 | B6: G100000409931 | C6: https://www.gem.wiki/Balikpapan_Refinery_power_plant | D6: Indonesia | E6: Balikpapan Refinery power plant | H6: 1 | I6: fossil gas: natural gas | J6: 56 | K6: construction | L6: gas turbine | M6: Siemens Energy: SGT-800 | N6: not found | O6: not found | P6: not found | V6: 2025 | Z6: Balikpapan Refinery [100%] | AA6: E100000002501 [100%] | AB6: PT Pertamina (Persero) [100.0%] | AC6: E100000000538 [100.0%] | AD6: 1.578726 | AE6: 114.60876 | AF6: approximate | AG6: Balikpapan | AJ6: East Kalimantan | AK6: South-eastern Asia | AL6: Asia | AO6: power | AP6: oil & refining | AR6: Gas only
A7: L100000407608 | B7: G100000409930 | C7: https://www.gem.wiki/Balikpapan_Refinery_power_plant | D7: Indonesia | E7: Balikpapan Refinery power plant | H7: 2 | I7: fossil gas: natural gas | J7: 56 | K7: construction | L7: gas turbine | M7: Siemens Energy: SGT-800 | N7: not found | O7: not found | P7: not found | V7: 2025 | Z7: Balikpapan Refinery [100%] | AA7: E100000002501 [100%] | AB7: PT Pertamina (Persero) [100.0%] | AC7: E100000000538 [100.0%] | AD7: 1.578726 | AE7: 114.60876 | AF7: approximate | AG7: Balikpapan | AJ7: East Kalimantan | AK7: South-eastern Asia | AL7: Asia | AO7: power | AP7: oil & refining | AR7: Gas only
A8: L100000407608 | B8: G100000409929 | C8: https://www.gem.wiki/Balikpapan_Refinery_power_plant | D8: Indonesia | E8: Balikpapan Refinery power plant | H8: 3 | I8: fossil gas: natural gas | J8: 56 | K8: construction | L8: gas turbine | M8: Siemens Energy: SGT-800 | N8: not found | O8: not found | P8: not found | V8: 2025 | Z8: Balikpapan Refinery [100%] | AA8: E100000002501 [100%] | AB8: PT Pertamina (Persero) [100.0%] | AC8: E100000000538 [100.0%] | AD8: 1.578726 | AE8: 114.60876 | AF8: approximate | AG8: Balikpapan | AJ8: East Kalimantan | AK8: South-eastern Asia | AL8: Asia | AO8: power | AP8: oil & refining | AR8: Gas only
A9: L100000407608 | B9: G100000409928 | C9: https://www.gem.wiki/Balikpapan_Refinery_power_plant | D9: Indonesia | E9: Balikpapan Refinery power plant | H9: 4 | I9: fossil gas: natural gas | J9: 56 | K9: construction | L9: gas turbine | M9: Siemens Energy: SGT-800 | N9: not found | O9: not found | P9: not found | V9: 2025 | Z9: Balikpapan Refinery [100%] | AA9: E100000002501 [100%] | AB9: PT Pertamina (Persero) [100.0%] | AC9: E100000000538 [100.0%] | AD9: 1.578726 | AE9: 114.60876 | AF9: approximate | AG9: Balikpapan | AJ9: East Kalimantan | AK9: South-eastern Asia | AL9: Asia | AO9: power | AP9: oil & refining | AR9: Gas only
A10: L100000408065 | B10: G100000411328 | C10: https://www.gem.wiki/Bangkanai_I_power_station | D10: Indonesia | E10: Bangkanai I power station | H10: 1 | I10: fossil gas: natural gas | J10: 144 | K10: operating | L10: internal combustion | N10: not found | P10: not found | V10: not found | Z10: PT PLN (Persero) [100%] | AA10: E100000000537 [100%] | AB10: PT PLN (Persero) [100.0%] | AC10: E100000000537 [100.0%] | AD10: -0.621886 | AE10: 115.13707 | AF10: exact | AG10: Kab Barito Utara | AJ10: Central Kalimantan | AK10: South-eastern Asia | AL10: Asia | AR10: Gas only
A11: L100000408064 | B11: G100000411327 | C11: https://www.gem.wiki/Bangkanai_II_power_station | D11: Indonesia | E11: Bangkanai II power station | H11: 1 | I11: fossil gas: natural gas | J11: 140 | K11: operating | L11: internal combustion | N11: not found | P11: not found | V11: 2022 | Z11: PT PLN (Persero) [100%] | AA11: E100000000537 [100%] | AB11: PT PLN (Persero) [100.0%] | AC11: E100000000537 [100.0%] | AD11: -0.62081 | AE11: 115.114 | AF11: exact | AG11: Kab Barito Utara | AJ11: Central Kalimantan | AK11: South-eastern Asia | AL11: Asia | AR11: Gas only
A12: L100000405263 | B12: G100000400917 | C12: https://www.gem.wiki/Bantaeng_LNG_power_station | D12: Indonesia | E12: Bantaeng LNG power station | H12: 1 | I12: fossil gas: LNG | J12: 600 | K12: cancelled - inferred 4 y | L12: combined cycle | N12: not found | P12: not found | Z12: PT Energi Nusantara Merah Putih [100%] | AA12: E100000001947 [100%] | AB12: PT Energi Nusantara Merah Putih [100.0%] | AC12: E100000001947 [100.0%] | AD12: -5.471156 | AE12: 119.83763 | AF12: approximate | AG12: Bantaeng | AJ12: South Sulawesi | AK12: South-eastern Asia | AL12: Asia | AR12: LNG only
A13: L100000408063 | B13: G100000411326 | C13: https://www.gem.wiki/Batamindo_Industrial_Park_power_station | D13: Indonesia | E13: Batamindo Industrial Park power station | H13: 1 | I13: fossil gas: natural gas, fossil liquids: fuel oil | J13: 114 | K13: operating | L13: internal combustion | N13: not found | P13: not found | V13: 2006 | Z13: PT Batamindo Investment Cakrawala [100%] | AA13: E100001010521 [100%] | AB13: Gallant Venture Ltd [100.0%] | AC13: E100001011137 [100.0%] | AD13: 1.068868 | AE13: 104.02519 | AF13: approximate | AG13: Mukakuning - Pulau Batam | AJ13: Riau | AK13: South-eastern Asia | AL13: Asia | AR13: Multi fuel
A14: L100000102828 | B14: G100000411720 | C14: https://www.gem.wiki/Batu_Hijau_power_station | D14: Indonesia | E14: Batu Hijau power station | G14: Amman Mineral power station, 安曼矿业发电站 | H14: CC1 | I14: fossil gas: LNG | J14: 450 | K14: construction | L14: combined cycle | M14: Siemens Energy: SGT-800 | Q14: replacement | R14: coal: unknown, coal: unknown, coal: unknown, coal: unknown | S14: G100000100662, G100000100663, G100000100664, G100000100665 | V14: 2025 | Z14: PT Amman Mineral Nusa Tenggara | AA14: E100001011092 | AB14: PT Amman Mineral Internasional Tbk | AC14: E100001011093 | AD14: -8.901172 | AE14: 116.73821 | AF14: exact | AG14: Batu Hijau gold mine | AH14: Maluk | AI14: Sumbawa Barat | AJ14: West Nusa Tenggara | AK14: South-eastern Asia | AL14: Asia | AO14: power | AP14: other metals & mining | AR14: LNG only
A15: L100000406379 | B15: G100000406288 | C15: https://www.gem.wiki/Batubara_power_station | D15: Indonesia | E15: Batubara power station | H15: 45691 | I15: fossil gas: natural gas | J15: 800 | K15: announced | L15: combined cycle | N15: not found | O15: not found | P15: not found | V15: not found | Z15: PT Hanlim Power Corp [100%] | AA15: E100000003756 [100%] | AB15: Hanlim Power Corp [100.0%] | AC15: E100000000939 [100.0%] | AD15: 3.285553 | AE15: 99.508176 | AF15: approximate | AG15: Perupuk | AH15: Limapuluh | AI15: Batubara | AJ15: North Sumatra | AK15: South-eastern Asia | AL15: Asia | AR15: Gas only
A16: L100000406379 | B16: G100000406291 | C16: https://www.gem.wiki/Batubara_power_station | D16: Indonesia | E16: Batubara power station | H16: 45659 | I16: fossil gas: natural gas | J16: 800 | K16: cancelled - inferred 4 y | L16: combined cycle | N16: not found | O16: not found | P16: not found | Z16: PT Hanlim Power Corp [100%] | AA16: E100000003756 [100%] | AB16: Hanlim Power Corp [100.0%] | AC16: E100000000939 [100.0%] | AD16: 3.285553 | AE16: 99.508176 | AF16: approximate | AG16: Perupuk | AH16: Limapuluh | AI16: Batubara | AJ16: North Sumatra | AK16: South-eastern Asia | AL16: Asia | AR16: Gas only
A17: L100000406379 | B17: G100000406290 | C17: https://www.gem.wiki/Batubara_power_station | D17: Indonesia | E17: Batubara power station | H17: 45690 | I17: fossil gas: natural gas | J17: 800 | K17: cancelled - inferred 4 y | L17: combined cycle | N17: not found | O17: not found | P17: not found | Z17: PT Hanlim Power Corp [100%] | AA17: E100000003756 [100%] | AB17: Hanlim Power Corp [100.0%] | AC17: E100000000939 [100.0%] | AD17: 3.285553 | AE17: 99.508176 | AF17: approximate | AG17: Perupuk | AH17: Limapuluh | AI17: Batubara | AJ17: North Sumatra | AK17: South-eastern Asia | AL17: Asia | AR17: Gas only
A18: L100000406379 | B18: G100000406289 | C18: https://www.gem.wiki/Batubara_power_station | D18: Indonesia | E18: Batubara power station | H18: 45660 | I18: fossil gas: natural gas | J18: 800 | K18: cancelled - inferred 4 y | L18: combined cycle | N18: not found | O18: not found | P18: not found | Z18: PT Hanlim Power Corp [100%] | AA18: E100000003756 [100%] | AB18: Hanlim Power Corp [100.0%] | AC18: E100000000939 [100.0%] | AD18: 3.285553 | AE18: 99.508176 | AF18: approximate | AG18: Perupuk | AH18: Limapuluh | AI18: Batubara | AJ18: North Sumatra | AK18: South-eastern Asia | AL18: Asia | AR18: Gas only
A19: L100000406379 | B19: G100000406293 | C19: https://www.gem.wiki/Batubara_power_station | D19: Indonesia | E19: Batubara power station | H19: 45658 | I19: fossil gas: natural gas | J19: 800 | K19: construction | L19: combined cycle | M19: not found | N19: not found | P19: not found | V19: 2024 | Z19: PT Hanlim Power Corp [100%] | AA19: E100000003756 [100%] | AB19: Hanlim Power Corp [100.0%] | AC19: E100000000939 [100.0%] | AD19: 3.285553 | AE19: 99.508176 | AF19: approximate | AG19: Perupuk | AH19: Limapuluh | AI19: Batubara | AJ19: North Sumatra | AK19: South-eastern Asia | AL19: Asia | AR19: Gas only
A20: L100000406379 | B20: G100000406292 | C20: https://www.gem.wiki/Batubara_power_station | D20: Indonesia | E20: Batubara power station | H20: 45689 | I20: fossil gas: natural gas | J20: 800 | K20: construction | L20: combined cycle | M20: not found | N20: not found | P20: not found | V20: 2024 | Z20: PT Hanlim Power Corp [100%] | AA20: E100000003756 [100%] | AB20: Hanlim Power Corp [100.0%] | AC20: E100000000939 [100.0%] | AD20: 3.285553 | AE20: 99.508176 | AF20: approximate | AG20: Perupuk | AH20: Limapuluh | AI20: Batubara | AJ20: North Sumatra | AK20: South-eastern Asia | AL20: Asia | AR20: Gas only
A21: L100000405264 | B21: G100000404255 | C21: https://www.gem.wiki/Bekasi_power_station | D21: Indonesia | E21: Bekasi power station | H21: 1 | I21: fossil gas: natural gas | J21: 130 | K21: operating | L21: combined cycle | N21: not found | P21: not found | V21: 2013 | Z21: PT Bekasi Power [100%] | AA21: E100000003754 [100%] | AB21: PT Kawasan Industri Jababeka Tbk [100.0%] | AC21: E100000120663 [100.0%] | AD21: -6.269558 | AE21: 107.15968 | AF21: exact | AG21: Cikarang | AJ21: West Java | AK21: South-eastern Asia | AL21: Asia | AM21: World Resources Institute: WRI1000870 | AR21: Gas only
A22: L100000405264 | B22: G100000404256 | C22: https://www.gem.wiki/Bekasi_power_station | D22: Indonesia | E22: Bekasi power station | H22: 2 | I22: fossil gas: natural gas | J22: 130 | K22: shelved - inferred 2 y | L22: unknown | N22: not found | P22: not found | Z22: PT Bekasi Power [100%] | AA22: E100000003754 [100%] | AB22: PT Kawasan Industri Jababeka Tbk [100.0%] | AC22: E100000120663 [100.0%] | AD22: -6.269558 | AE22: 107.15968 | AF22: exact | AG22: Cikarang | AJ22: West Java | AK22: South-eastern Asia | AL22: Asia | AM22: World Resources Institute: WRI1000870 | AR22: Gas only
A23: L100000408067 | B23: G100000411325 | C23: https://www.gem.wiki/Belawan_Berkat_power_station | D23: Indonesia | E23: Belawan Berkat power station | H23: 1 | I23: fossil liquids: fuel oil | J23: 160 | K23: operating | L23: internal combustion | N23: not found | P23: not found | V23: 2014 | Z23: PT Berkat Bima Sentana [100%] | AA23: E100001010522 [100%] | AB23: PT Berkat Bima Sentana [100.0%] | AC23: E100001010522 [100.0%] | AD23: 3.771713 | AE23: 98.66769 | AF23: approximate | AG23: Kab Karo - Medan | AJ23: North Sumatra | AK23: South-eastern Asia | AL23: Asia | AM23: World Resources Institute: WRI1000817, World Resources Institute: WRI1000818 | AR23: Oil only
A24: L100000405265 | B24: G100000405915 | C24: https://www.gem.wiki/Belawan_power_station | D24: Indonesia | E24: Belawan power station | G24: Belawan Thermal Power Plant | H24: 45660 | I24: fossil gas: LNG | J24: 430 | K24: cancelled | L24: combined cycle | N24: not found | O24: not found | P24: not found | Z24: PT PLN (Persero) [100%] | AA24: E100000000537 [100%] | AB24: PT PLN (Persero) [100.0%] | AC24: E100000000537 [100.0%] | AD24: 3.773148 | AE24: 98.670029 | AF24: exact | AG24: Belawan | AJ24: North Sumatra | AK24: South-eastern Asia | AL24: Asia | AM24: World Resources Institute: WRI1000817, World Resources Institute: WRI1000818 | AR24: LNG only
A25: L100000405265 | B25: G100000405909 | C25: https://www.gem.wiki/Belawan_power_station | D25: Indonesia | E25: Belawan power station | G25: Belawan Thermal Power Plant | H25: 45658 | I25: fossil gas: natural gas, fossil liquids: fuel oil | J25: 65 | K25: operating | L25: steam turbine | N25: not found | P25: not found | V25: 1984 | Z25: PT PLN (Persero) [100%] | AA25: E100000000537 [100%] | AB25: PT PLN (Persero) [100.0%] | AC25: E100000000537 [100.0%] | AD25: 3.773148 | AE25: 98.670029 | AF25: exact | AG25: Belawan | AJ25: North Sumatra | AK25: South-eastern Asia | AL25: Asia | AM25: World Resources Institute: WRI1000817, World Resources Institute: WRI1000818 | AR25: Multi fuel
A26: L100000405265 | B26: G100000405910 | C26: https://www.gem.wiki/Belawan_power_station | D26: Indonesia | E26: Belawan power station | G26: Belawan Thermal Power Plant | H26: 45689 | I26: fossil gas: natural gas, fossil liquids: fuel oil | J26: 65 | K26: operating | L26: steam turbine | N26: not found | P26: not found | V26: 1984 | Z26: PT PLN (Persero) [100%] | AA26: E100000000537 [100%] | AB26: PT PLN (Persero) [100.0%] | AC26: E100000000537 [100.0%] | AD26: 3.773148 | AE26: 98.670029 | AF26: exact | AG26: Belawan | AJ26: North Sumatra | AK26: South-eastern Asia | AL26: Asia | AM26: World Resources Institute: WRI1000817, World Resources Institute: WRI1000818 | AR26: Multi fuel
A27: L100000405265 | B27: G100000405911 | C27: https://www.gem.wiki/Belawan_power_station | D27: Indonesia | E27: Belawan power station | G27: Belawan Thermal Power Plant | H27: 45717 | I27: fossil gas: natural gas, fossil liquids: fuel oil | J27: 65 | K27: operating | L27: steam turbine | N27: not found | P27: not found | V27: 1984 | Z27: PT PLN (Persero) [100%] | AA27: E100000000537 [100%] | AB27: PT PLN (Persero) [100.0%] | AC27: E100000000537 [100.0%] | AD27: 3.773148 | AE27: 98.670029 | AF27: exact | AG27: Belawan | AJ27: North Sumatra | AK27: South-eastern Asia | AL27: Asia | AM27: World Resources Institute: WRI1000817, World Resources Institute: WRI1000818 | AR27: Multi fuel
A28: L100000405265 | B28: G100000405912 | C28: https://www.gem.wiki/Belawan_power_station | D28: Indonesia | E28: Belawan power station | G28: Belawan Thermal Power Plant | H28: 45748 | I28: fossil gas: natural gas, fossil liquids: fuel oil | J28: 65 | K28: operating | L28: steam turbine | N28: not found | P28: not found | V28: 1984 | Z28: PT PLN (Persero) [100%] | AA28: E100000000537 [100%] | AB28: PT PLN (Persero) [100.0%] | AC28: E100000000537 [100.0%] | AD28: 3.773148 | AE28: 98.670029 | AF28: exact | AG28: Belawan | AJ28: North Sumatra | AK28: South-eastern Asia | AL28: Asia | AM28: World Resources Institute: WRI1000817, World Resources Institute: WRI1000818 | AR28: Multi fuel
A29: L100000405265 | B29: G100000405913 | C29: https://www.gem.wiki/Belawan_power_station | D29: Indonesia | E29: Belawan power station | G29: Belawan Thermal Power Plant | H29: 45659 | I29: fossil gas: natural gas, fossil liquids: diesel | J29: 395 | K29: operating | L29: combined cycle | N29: not found | P29: not found | V29: 1994 | Z29: PT PLN (Persero) [100%] | AA29: E100000000537 [100%] | AB29: PT PLN (Persero) [100.0%] | AC29: E100000000537 [100.0%] | AD29: 3.773148 | AE29: 98.670029 | AF29: exact | AG29: Belawan | AJ29: North Sumatra | AK29: South-eastern Asia | AL29: Asia | AM29: World Resources Institute: WRI1000817, World Resources Institute: WRI1000818 | AR29: Multi fuel
A30: L100000405265 | B30: G100000405914 | C30: https://www.gem.wiki/Belawan_power_station | D30: Indonesia | E30: Belawan power station | G30: Belawan Thermal Power Plant | H30: 45690 | I30: fossil gas: natural gas, fossil liquids: diesel | J30: 422 | K30: operating | L30: combined cycle | N30: not found | P30: not found | V30: 1994 | Z30: PT PLN (Persero) [100%] | AA30: E100000000537 [100%] | AB30: PT PLN (Persero) [100.0%] | AC30: E100000000537 [100.0%] | AD30: 3.773148 | AE30: 98.670029 | AF30: exact | AG30: Belawan | AJ30: North Sumatra | AK30: South-eastern Asia | AL30: Asia | AM30: World Resources Institute: WRI1000817, World Resources Institute: WRI1000818 | AR30: Multi fuel
A31: L100000408066 | B31: G100000411324 | C31: https://www.gem.wiki/BMPP_Nusantara-1_power_station | D31: Indonesia | E31: BMPP Nusantara-1 power station | H31: 1 | I31: fossil liquids: diesel, fossil gas: LNG | J31: 60 | K31: operating | L31: internal combustion | M31: Wärtsilä: 20V34DF | N31: not found | P31: not found | V31: 2022 | Z31: PT PLN (Persero) [100%] | AA31: E100000000537 [100%] | AB31: PT PLN (Persero) [100.0%] | AC31: E100000000537 [100.0%] | AD31: -3.550482 | AE31: 128.33573 | AF31: exact | AG31: Pulau Ambon | AJ31: Maluku | AK31: South-eastern Asia | AL31: Asia | AR31: Multi fuel
A32: L100001048420 | B32: G100001055585 | C32: https://www.gem.wiki/BMPP_Nusantara-2_power_station | D32: Indonesia | E32: BMPP Nusantara-2 power station | H32: 1 | I32: fossil gas: LNG, fossil liquids: diesel | J32: 60 | K32: operating | L32: internal combustion | M32: Wärtsilä: 20V34DF | N32: no | V32: 2024 | Z32: PT PLN Indonesia Power | AA32: E100000003758 | AB32: PT PLN (Persero) | AC32: E100000000537 | AD32: -3.891103 | AE32: 121.27963 | AF32: approximate | AH32: Wolo | AI32: Kolaka | AJ32: Southeast Sulawesi | AK32: South-eastern Asia | AL32: Asia | AO32: power | AP32: iron & steel | AR32: Multi fuel
A33: L100000405266 | B33: G100000404302 | C33: https://www.gem.wiki/Borang_power_station | D33: Indonesia | E33: Borang power station | H33: 1 | I33: fossil gas: natural gas | J33: 100 | K33: operating | L33: combined cycle | N33: not found | P33: not found | V33: not found | Z33: PT PLN (Persero) [100%] | AA33: E100000000537 [100%] | AB33: PT PLN (Persero) [100.0%] | AC33: E100000000537 [100.0%] | AD33: -2.92344 | AE33: 104.87107 | AF33: approximate | AG33: Perajen | AJ33: South Sumatra | AK33: South-eastern Asia | AL33: Asia | AR33: Gas only
A34: L100000408069 | B34: G100000411323 | C34: https://www.gem.wiki/Cilegon_KDL_power_station | D34: Indonesia | E34: Cilegon KDL power station | H34: 1 | I34: fossil gas: natural gas, fossil liquids: fuel oil | J34: 80 | K34: operating | L34: steam turbine | N34: not found | P34: not found | V34: 1978 | Z34: PT Krakatau Daya Listrik [100%] | AA34: E100000001949 [100%] | AB34: PT Krakatau Steel (Persero) Tbk [100.0%] | AC34: E100001010136 [100.0%] | AD34: -5.994087 | AE34: 105.98413 | AF34: exact | AG34: Cilegon | AJ34: Banten | AK34: South-eastern Asia | AL34: Asia | AR34: Multi fuel
A35: L100000408069 | B35: G100000411322 | C35: https://www.gem.wiki/Cilegon_KDL_power_station | D35: Indonesia | E35: Cilegon KDL power station | H35: 2 | I35: fossil gas: natural gas | J35: 120 | K35: operating | L35: combined cycle | N35: not found | P35: not found | V35: 2015 | Z35: PT Krakatau Daya Listrik [100%] | AA35: E100000001949 [100%] | AB35: PT Krakatau Steel (Persero) Tbk [100.0%] | AC35: E100001010136 [100.0%] | AD35: -5.994087 | AE35: 105.98413 | AF35: exact | AG35: Cilegon | AJ35: Banten | AK35: South-eastern Asia | AL35: Asia | AR35: Gas only
A36: L100000408069 | B36: G100000411321 | C36: https://www.gem.wiki/Cilegon_KDL_power_station | D36: Indonesia | E36: Cilegon KDL power station | H36: 3 | I36: fossil gas: natural gas, fossil liquids: fuel oil | J36: 80 | K36: operating | L36: steam turbine | N36: not found | P36: not found | V36: 1978 | Z36: PT Krakatau Daya Listrik [100%] | AA36: E100000001949 [100%] | AB36: PT Krakatau Steel (Persero) Tbk [100.0%] | AC36: E100001010136 [100.0%] | AD36: -5.994087 | AE36: 105.98413 | AF36: exact | AG36: Cilegon | AJ36: Banten | AK36: South-eastern Asia | AL36: Asia | AR36: Multi fuel
A37: L100000408069 | B37: G100000411320 | C37: https://www.gem.wiki/Cilegon_KDL_power_station | D37: Indonesia | E37: Cilegon KDL power station | H37: 4 | I37: fossil gas: natural gas, fossil liquids: fuel oil | J37: 80 | K37: operating | L37: steam turbine | N37: not found | P37: not found | V37: 1978 | Z37: PT Krakatau Daya Listrik [100%] | AA37: E100000001949 [100%] | AB37: PT Krakatau Steel (Persero) Tbk [100.0%] | AC37: E100001010136 [100.0%] | AD37: -5.994087 | AE37: 105.98413 | AF37: exact | AG37: Cilegon | AJ37: Banten | AK37: South-eastern Asia | AL37: Asia | AR37: Multi fuel
A38: L100000408069 | B38: G100000411319 | C38: https://www.gem.wiki/Cilegon_KDL_power_station | D38: Indonesia | E38: Cilegon KDL power station | H38: 5 | I38: fossil gas: natural gas, fossil liquids: fuel oil | J38: 80 | K38: operating | L38: steam turbine | N38: not found | P38: not found | V38: 1978 | Z38: PT Krakatau Daya Listrik [100%] | AA38: E100000001949 [100%] | AB38: PT Krakatau Steel (Persero) Tbk [100.0%] | AC38: E100001010136 [100.0%] | AD38: -5.994087 | AE38: 105.98413 | AF38: exact | AG38: Cilegon | AJ38: Banten | AK38: South-eastern Asia | AL38: Asia | AR38: Multi fuel
A39: L100000408069 | B39: G100000411318 | C39: https://www.gem.wiki/Cilegon_KDL_power_station | D39: Indonesia | E39: Cilegon KDL power station | H39: 6 | I39: fossil gas: natural gas, fossil liquids: fuel oil | J39: 80 | K39: operating | L39: steam turbine | N39: not found | P39: not found | V39: 1978 | Z39: PT Krakatau Daya Listrik [100%] | AA39: E100000001949 [100%] | AB39: PT Krakatau Steel (Persero) Tbk [100.0%] | AC39: E100001010136 [100.0%] | AD39: -5.994087 | AE39: 105.98413 | AF39: exact | AG39: Cilegon | AJ39: Banten | AK39: South-eastern Asia | AL39: Asia | AR39: Multi fuel
A40: L100000405267 | B40: G100000404257 | C40: https://www.gem.wiki/Cilegon_power_station | D40: Indonesia | E40: Cilegon power station | H40: 1 | I40: fossil gas: natural gas | J40: 740 | K40: operating | L40: combined cycle | N40: not found | P40: not found | V40: 2007 | Z40: PT PLN Indonesia Power [100%] | AA40: E100000003758 [100%] | AB40: PT PLN (Persero) [100.0%] | AC40: E100000000537 [100.0%] | AD40: -5.9306 | AE40: 106.1042 | AF40: exact | AG40: Margasari | AJ40: Banten | AK40: South-eastern Asia | AL40: Asia | AM40: World Resources Institute: WRI1000874 | AR40: Gas only
...

Sheet from TA
A1: NO | B1: NAMA PEMBANGKIT | C1: LOKASI | D1: KAPASITAS (MW) | E1: COD | F1: Main sheet | G1: Note | H1: Color meaning
A2: 1 | B2: PLTG GILIMANUK #1 | C2: BALI | D2: 133.8 | F2: x | H2: x | I2: Already in the main sheet
A3: 2 | B3: PLTG PEMARON #1 | D3: 48.8 | I3: Not in the main sheet but already input in main sheet
A4: 3 | B4: PLTG PEMARON #2 | D4: 48.8 | I4: Ambiguous and still not listed in main sheet
A5: 4 | B5: PLTG PESANGGARAN #1 | D5: 21.35
A6: 5 | B6: PLTG PESANGGARAN #2 | D6: 20.1
A7: 6 | B7: PLTG PESANGGARAN #3 | D7: 42
A8: 7 | B8: PLTG PESANGGARAN #4 | D8: 42
A9: 8 | B9: PLTG PESANGGARAN #5 Ex PLTGU Grati #1 | D9: 100.75 | F9: x
A10: 9 | B10: PLTG PESANGGARAN #6 EX PLTGU Grati #3 | D10: 100.75 | F10: x
A11: 10 | B11: DSS_TNG PLTG #1 | C11: BANTEN | D11: 4.2
A12: 11 | B12: DSS_TNG PLTG #2 | D12: 4.2
A13: 12 | B13: PLTG MALEO #1 | C13: GORONTALO | D13: 25 | F13: x | G13: Gorontalo power station 100 MW in main sheet
A14: 13 | B14: PLTG MALEO #2 | D14: 25 | F14: x | G14: Gorontalo power station 100 MW in main sheet
A15: 14 | B15: PLTG MALEO #3 | D15: 25 | F15: x | G15: Gorontalo power station 100 MW in main sheet
A16: 15 | B16: PLTG MALEO #4 | D16: 25 | F16: x | G16: Gorontalo power station 100 MW in main sheet
A17: 16 | B17: PLTG BATANG HARI #1 | C17: JAMBI | D17: 30 | G17: Relocated to 41
A18: 17 | B18: PLTG BATANG HARI #2 | D18: 30 | G18: Relocated to 41
A19: 18 | B19: PLTG BOT PAYO #1 EX PT ERAMAS PERSADA ENERGY | D19: 46.78 | F19: x | G19: Payo Selincah power station 50 MW in main sheet
A20: 19 | B20: PLTG PAYO SELINCAH #2 EX PLTG BOT PAYO SELINCAH #2 | D20: 50 | F20: x | G20: Payo Selincah power station 50 MW in main sheet
A21: 20 | B21: PLTG CILACAP #1 | C21: JAWA TENGAH | D21: 29
A22: 21 | B22: PLTG CILACAP #2 | D22: 26
A23: 22 | B23: PLTG IPP MPP PARIT BARU #1 (PT PLN BATAM) | C23: KALIMANTAN BARAT | D23: 50
A24: 23 | B24: PLTG IPP MPP PARIT BARU #2 (PT PLN BATAM) | D24: 50
A25: 24 | B25: PLTG SIANTAN #1 (EGT ALSTOM) | D25: 34
A26: 25 | B26: PLTMG ARUN | C26: ACEH | E26: 2016 | G26: capacity?
A27: 26 | B27: PLTG TRISAKTI #1 | C27: KALIMANTAN SELATAN | D27: 21.55
A28: 27 | B28: ALSTOM | C28: KALIMANTAN TIMUR | D28: 34 | F28: x | G28: Most likely Kaltim power station in main sheet
A29: 28 | B29: PLTG PEAKING #1 (GE 1) | D29: 80 | F29: x | G29: Most likely Kaltim power station in main sheet
A30: 29 | B30: PLTG PEAKING #2 (GE 2) | D30: 80 | F30: x | G30: Most likely Kaltim power station in main sheet
A31: 30 | B31: PLTG SEMBERAH #1 | D31: 20
A32: 31 | B32: PLTG SEMBERAH #2 | D32: 20
A33: 32 | B33: PLTG SW TARAKAN (PERSUDA) | C33: KALIMANTAN UTARA | D33: 15.6
A34: 33 | B34: PLTG IPP MPP AIR ANYIR (PT PLN BATAM) | C34: BANGKA BELITUNG | D34: 75
A35: 34 | B35: PLTG IPP MPP SUGE (PT PLN BATAM) | D35: 25
A36: 35 | B36: PANARAN 1 | C36: KEP. RIAU | D36: 65.16 | F36: x | G36: Panaran power station in main sheet
A37: 36 | B37: PANARAN 2 | D37: 64.6 | F37: x | G37: Panaran power station in main sheet
A38: 37 | B38: T. UNCANG (ELB) | D38: 70
A39: 38 | B39: PLTG IPP MPP TARAHAN (PT PLN BATAM) | C39: LAMPUNG | D39: 100
A40: 39 | B40: PLTG SEBALANG #1 EX PLTG PAUH LIMO #2 | D40: 21.5
...
