Workbook

Sheet Legend
C2: data missing
C3: different GEM information
C4: needs verification
C5: not in IESR data
B7: Summary | C7: IESR data | D7: GEM
B8: Operating | C8: =SUMIF('PLN & IPP'!N:N,B8,'PLN & IPP'!C:C) -> 31481 | D8: =SUMIF(GEM!M:M,B8,GEM!L:L) -> 30767
B9: Construction | C9: =SUMIF('PLN & IPP'!N:N,B9,'PLN & IPP'!C:C)+SUMIF('PLN & IPP'!N:N,"On going construction",'PLN & IPP'!C:C) -> 10629 | D9: =SUMIF(GEM!M:M,B9,GEM!L:L) -> 10339
B10: Permitted | C10: =SUMIF('PLN & IPP'!N:N,B10,'PLN & IPP'!C:C) -> 700 | D10: =SUMIF(GEM!M:M,B10,GEM!L:L) -> 700
B11: pre-permit | C11: =SUMIF('PLN & IPP'!N:N,B11,'PLN & IPP'!C:C) -> 900 | D11: =SUMIF(GEM!M:M,B11,GEM!L:L) -> 1700
B12: shelved | C12: =SUMIF('PLN & IPP'!N:N,B12,'PLN & IPP'!C:C) -> 2320 | D12: =SUMIF(GEM!M:M,B12,GEM!L:L) -> 3820
B16: Progress as of March 2022
B17: Projects with AMDALs | C17: Notes
B18: Bengkulu U1&2
B19: Celukan Bawang Unit 1-3
B20: Cilacap Unit 1-3 | C20: Not complete
B21: Cirebon 1
B22: Indramayu Unit 1-3
B23: Jawa-1 / Cirebon-2
B24: Jawa-4/Tanjung Jati B Unit 5&6
B25: Tanjung Jati B Unit 3&4
B26: Paiton Unit 3

Sheet all_status
A1: CFPP name | B1: GEM ID | C1: Owner | D1: Captive industry | E1: Capacity (MW) | F1: COD | G1: Status Jul 2024 | H1: Status Jan 2024 | I1: Status Jun 2023 | J1: Latitude | K1: Longitude | L1: Parent | M1: Province_EN | N1: Provinsi_ID
A2: Adaro Aluminum Smelter Phase I | B2: G115748 | C2: Captive | D2: Aluminum | E2: 1100 | F2: 2025 | G2: pre-permit | H2: pre-permit | I2: pre-permit | J2: 2.528 | K2: 117.858 | L2: PT Adaro Power | M2: North Kalimantan | N2: Kalimantan Utara
A3: Adaro Aluminum Smelter Phase II | B3: G115905 | C3: Captive | D3: Aluminum | E3: 1100 | F3: 2026 | G3: announced | H3: announced | I3: announced | J3: 2.528 | K3: 117.858 | L3: PT Adaro Power | M3: North Kalimantan | N3: Kalimantan Utara
A4: Ketapang Smelter Phase I, Unit 3 | B4: G105679 | C4: Captive | D4: Aluminum | E4: 30 | F4: 2016 | G4: operating | H4: operating | I4: operating | J4: -2.366182 | K4: 110.15727 | L4: China Hongqiao Group; Harita Group | M4: West Kalimantan | N4: Kalimantan Barat
A5: Ketapang Smelter Phase II, Unit 1 | B5: G114899 | C5: Captive | D5: Aluminum | E5: 80 | F5: 2021 | G5: operating | H5: operating | I5: operating | J5: -2.366182 | K5: 110.15727 | L5: China Hongqiao Group; Harita Group | M5: West Kalimantan | N5: Kalimantan Barat
A6: Ketapang Smelter Phase II, Unit 2 | B6: G114900 | C6: Captive | D6: Aluminum | E6: 80 | F6: 2021 | G6: operating | H6: operating | I6: operating | J6: -2.366182 | K6: 110.15727 | L6: China Hongqiao Group; Harita Group | M6: West Kalimantan | N6: Kalimantan Barat
A7: Ketapang Smelter Phase II, Unit 3 | B7: G105680 | C7: Captive | D7: Aluminum | E7: 30 | F7: 2021 | G7: operating | H7: operating | I7: operating | J7: -2.366182 | K7: 110.15727 | L7: China Hongqiao Group; Harita Group | M7: West Kalimantan | N7: Kalimantan Barat
A8: Kuala Tanjung Inalum captive / Sumut-2 Unit 1 | B8: G105993 | C8: Captive | D8: Aluminum | E8: 300 | F8: 2023 | G8: cancelled | H8: cancelled | I8: cancelled | J8: 3.3506353 | K8: 99.451332 | L8: PT Bukit Asam [100.0%] | M8: North Sumatra | N8: Sumatra Utara
A9: Kuala Tanjung Inalum captive / Sumut-2 Unit 2 | B9: G105994 | C9: Captive | D9: Aluminum | E9: 300 | F9: 2024 | G9: cancelled | H9: cancelled | I9: cancelled | J9: 3.3506353 | K9: 99.451332 | L9: PT Bukit Asam [100.0%] | M9: North Sumatra | N9: Sumatra Utara
A10: Kuala Tanjung Inalum captive Unit 3 | B10: G105995 | C10: Captive | D10: Aluminum | E10: 350 | F10: 0 | G10: cancelled | H10: cancelled | I10: cancelled | J10: 3.3506353 | K10: 99.451332 | L10: PT Bukit Asam; PT Indonesia Asahan Aluminium | M10: North Sumatra | N10: Sumatra Utara
A11: NALCO East Kutai Unit 1 | B11: G107201 | C11: Captive | D11: Aluminum | E11: 250 | F11: 0 | G11: cancelled | H11: cancelled | I11: cancelled | J11: 1.254 | K11: 116.682 | L11: MEC Coal; Nalco Holding Co | M11: East Kalimantan | N11: Kalimantan Timur
A12: NALCO East Kutai Unit 2 | B12: G107202 | C12: Captive | D12: Aluminum | E12: 250 | F12: 0 | G12: cancelled | H12: cancelled | I12: cancelled | J12: 1.254 | K12: 116.682 | L12: MEC Coal; Nalco Holding Co | M12: East Kalimantan | N12: Kalimantan Timur
A13: NALCO East Kutai Unit 3 | B13: G107203 | C13: Captive | D13: Aluminum | E13: 250 | F13: 0 | G13: cancelled | H13: cancelled | I13: cancelled | J13: 1.254 | K13: 116.682 | L13: MEC Coal; Nalco Holding Co | M13: East Kalimantan | N13: Kalimantan Timur
... A52: Adaro East Kalimantan Unit 2 | B52: G100038 | C52: Captive | D52: Coal mining - Power generation | E52: 300 | F52: 0 | G52: cancelled | H52: cancelled | I52: cancelled | J52: 0.1 | K52: 116.4 | L52: China Energy Investment Corp; PT Adaro Power | M52: East Kalimantan | N52: Kalimantan Timur
A53: Astratel Phase I | B53: G100391 | C53: Captive | D53: Coal mining - Power generation | E53: 100 | F53: 0 | G53: cancelled | H53: cancelled | I53: cancelled | J53: -2.75 | K53: 103.83333 | L53: Astra International | M53: 0 | N53: 0
A54: DSS Serang Unit 1 | B54: G115073 | C54: Captive | D54: Coal mining - Power generation | E54: 35 | F54: 2016 | G54: operating | H54: operating | I54: operating | J54: -6.125435 | K54: 106.2892 | L54: PT Dian Swastatika Sentosa [100.0%] | M54: Banten | N54: Banten
A55: DSS Serang Unit 2 | B55: G115074 | C55: Captive | D55: Coal mining - Power generation | E55: 35 | F55: 2016 | G55: operating | H55: operating | I55: operating | J55: -6.125435 | K55: 106.2892 | L55: PT Dian Swastatika Sentosa [100.0%] | M55: Banten | N55: Banten
A56: DSS Serang Unit 3 | B56: G115075 | C56: Captive | D56: Coal mining - Power generation | E56: 35 | F56: 2016 | G56: operating | H56: operating | I56: operating | J56: -6.125435 | K56: 106.2892 | L56: PT Dian Swastatika Sentosa [100.0%] | M56: Banten | N56: Banten
A57: DSS Serang Unit 4 | B57: G115076 | C57: Captive | D57: Coal mining - Power generation | E57: 70 | F57: 2016 | G57: operating | H57: operating | I57: operating | J57: -6.125435 | K57: 106.2892 | L57: PT Dian Swastatika Sentosa [100.0%] | M57: Banten | N57: Banten
A58: Jambi Tebo Unit 1 | B58: G104953 | C58: Captive | D58: Coal mining - Power generation | E58: 200 | F58: 0 | G58: cancelled | H58: cancelled | I58: cancelled | J58: -1.39 | K58: 102.42 | L58: Korea Electric Power Corp [100.0%] | M58: Jambi | N58: Jambi
A59: Jambi Tebo Unit 2 | B59: G104954 | C59: Captive | D59: Coal mining - Power generation | E59: 200 | F59: 0 | G59: cancelled | H59: cancelled | I59: cancelled | J59: -1.39 | K59: 102.42 | L59: Korea Electric Power Corp [100.0%] | M59: Jambi | N59: Jambi
A60: Mesuji Unit 1 | B60: G106887 | C60: Captive | D60: Coal mining - Power generation | E60: 350 | F60: 0 | G60: cancelled | H60: cancelled | I60: cancelled | J60: -4.012776 | K60: 105.46296 | L60: China Shenhua Energy [100.0%] | M60: Lampung | N60: Lampung
A61: Mesuji Unit 2 | B61: G106888 | C61: Captive | D61: Coal mining - Power generation | E61: 350 | F61: 0 | G61: cancelled | H61: cancelled | I61: cancelled | J61: -4.012776 | K61: 105.46296 | L61: China Shenhua Energy [100.0%] | M61: Lampung | N61: Lampung
A62: Pindo-Deli-Ii Unit 1 | B62: G107980 | C62: Captive | D62: Coal mining - Power generation | E62: 50 | F62: 2007 | G62: operating | H62: operating | I62: operating | J62: -6.385474 | K62: 107.34362 | L62: PT Dian Swastatika Sentosa [100.0%] | M62: West Java | N62: Jawa Barat
A63: Sinar Mas Jambi Unit 1 | B63: G109402 | C63: Captive | D63: Coal mining - Power generation | E63: 200 | F63: 0 | G63: cancelled | H63: cancelled | I63: cancelled | J63: -1.61 | K63: 101.91 | L63: PT Dian Swastatika Sentosa [100.0%] | M63: Jambi | N63: Jambi
A64: Sinar Mas Jambi Unit 2 | B64: G109403 | C64: Captive | D64: Coal mining - Power generation | E64: 200 | F64: 0 | G64: cancelled | H64: cancelled | I64: cancelled | J64: -1.61 | K64: 101.91 | L64: PT Dian Swastatika Sentosa [100.0%] | M64: Jambi | N64: Jambi
A65: Tabalong Wisesa Unit 1 | B65: G109792 | C65: Captive | D65: Coal mining - Power generation | E65: 30 | F65: 2013 | G65: operating | H65: operating | I65: operating | J65: -2.158586 | K65: 115.44593 | L65: PT Adaro Power | M65: South Kalimantan | N65: Kalimantan Tengah
... A214: Timah South Sumatra Unit 2 | B214: G110176 | C214: Captive | D214: Tin | E214: 150 | F214: 0 | G214: cancelled | H214: cancelled | I214: cancelled | J214: -3.539482 | K214: 103.75484 | L214: PT Timah [100.0%] | M214: South Sumatra | N214: Sumatra Selatan
A215: Bakrie Sangatta Unit 1 | B215: G100455 | C215: IPP | E215: 100 | F215: 0 | G215: cancelled | H215: cancelled | I215: cancelled | J215: 0.605 | K215: 117.481 | L215: Bakrie Group | M215: East Kalimantan | N215: Kalimantan Timur
A216: Bakrie Sangatta Unit 2 | B216: G100456 | C216: IPP | E216: 100 | F216: 0 | G216: cancelled | H216: cancelled | I216: cancelled | J216: 0.605 | K216: 117.481 | L216: Bakrie Group | M216: East Kalimantan | N216: Kalimantan Timur
A217: Bali | B217: G113818 | C217: IPP | E217: 135 | F217: 0 | G217: cancelled | H217: cancelled | I217: cancelled | J217: -8.447602 | K217: 115.12221 | L217: to be determined [100.0%] | M217: Bali | N217: Bali
A218: Bangko Tengah Unit 3 | B218: G100512 | C218: IPP | E218: 660 | F218: 0 | G218: cancelled | H218: cancelled | I218: cancelled | J218: -3.734 | K218: 103.759 | L218: China Huadian Group Corp [55.0%]; PT Bukit Asam Tbk [45.0%] | M218: South Sumatra | N218: Sumatra Selatan
A219: Bangko Tengah Unit 4 | B219: G100513 | C219: IPP | E219: 660 | F219: 0 | G219: cancelled | H219: cancelled | I219: cancelled | J219: -3.734 | K219: 103.759 | L219: China Huadian Group Corp [55.0%]; PT Bukit Asam Tbk [45.0%] | M219: South Sumatra | N219: Sumatra Selatan
A220: Banjarsari Unit 1 | B220: G100519 | C220: IPP | E220: 110 | F220: 2015 | G220: operating | H220: operating | I220: operating | J220: -3.72507 | K220: 103.69039 | L220: PT Bukit Asam Tbk [59.8%]; PT PLN (Persero) [37.2%]; other unknown/mixed entity types [3.0%] | M220: South Sumatra | N220: Sumatra Selatan
A221: Banjarsari Unit 2 | B221: G100520 | C221: IPP | E221: 110 | F221: 2015 | G221: operating | H221: operating | I221: operating | J221: -3.72507 | K221: 103.69039 | L221: PT Bukit Asam Tbk [59.8%]; PT PLN (Persero) [37.2%]; other unknown/mixed entity types [3.0%] | M221: South Sumatra | N221: Sumatra Selatan
A222: Banten BSE Unit 1 | B222: G114349 | C222: IPP | E222: 300 | F222: 2023 | G222: cancelled | H222: cancelled | I222: cancelled | J222: -6.485765 | K222: 106.03813 | L222: BTN Power; PT Biidznillah Tambang Nusantara | M222: Banten | N222: Banten
A223: Banten BSE Unit 2 | B223: G114350 | C223: IPP | E223: 300 | F223: 2023 | G223: cancelled | H223: cancelled | I223: cancelled | J223: -6.485765 | K223: 106.03813 | L223: BTN Power; PT Biidznillah Tambang Nusantara | M223: Banten | N223: Banten
A224: Banten Serang Unit 2 | B224: G113817 | C224: IPP | E224: 660 | F224: 2025 | G224: cancelled | H224: cancelled | I224: cancelled | J224: -5.882972 | K224: 106.04593 | L224: Genting Group | M224: Banten | N224: Banten
A225: Banten Unit 1 / Banten Serang | B225: G100536 | C225: IPP | E225: 660 | F225: 2017 | G225: operating | H225: operating | I225: operating | J225: -5.882972 | K225: 106.04593 | L225: Genting Group | M225: Banten | N225: Banten
A226: Banyuasin Unit 1 | B226: G100548 | C226: IPP | E226: 120 | F226: 2021 | G226: cancelled | H226: cancelled | I226: cancelled | J226: -3.347874 | K226: 103.90047 | L226: Oceanwide Holdings Co Ltd [85.0%]; PT Satya Abadi Semesta [10.0%]; China Power International Development Co Ltd [5.0%] | M226: South Sumatra | N226: Sumatra Selatan
...

Sheet PLN & IPP
A1: Data Source | B1: CFPP name | C1: Capacity (MW) | D1: GEM unit/phase ID | E1: GEM ID | F1: GCPT name - plant & unit | G1: Island | H1: In RUPTL 2021-2030 | I1: In RUPTL 2025-2034 | J1: Biomass Co-firing Status | K1: Biomass type | L1: Biomass share | M1: Gov. Prog. | N1: Status June 2023, JETP | O1: Status July 2024 | P1: Status July 2026 | Q1: COD | R1: COD_RUPTL 2025-2034 (Base) | S1: Retirement target | T1: Years in operation | U1: Capacity Group | V1: YO Group | W1: Owner | X1: Steam Tech. | Y1: Boiler Tech. | Z1: thermal_efficiency | AA1: Emission Control Tech. | AB1: Notes | AC1: Latitude | AD1: Longitude | AE1: Annual NOx, ton/year | AF1: Annual SOx, ton/year | AG1: Annual PMs, ton/year | AH1: Conc. NOx | AI1: Conc. SOx | AJ1: Conc. PM | AK1: Unit for gases | AL1: Hg in coal, ppb | AM1: Stack height (m) | AN1: Stack diameter (m) | AO1: Flue exit temp (℃) | AP1: Flue velocity (m/s) | AQ1: Link
A2: Priority | B2: Alor Unit 1 | C2: 3 | D2: NA | E2: NA | F2: <30 MW | G2: Nusa Tenggara | H2: Yes | J2: =iferror(vlookup(vlookup(B2,'Co-firing inputs'!B:C,2,false),'Co-firing inputs'!B:G,6,false),"None") -> None | N2: planned | O2: planned | Q2: 2025 | T2: =YEAR(today())-Q2 -> 1 | U2: =IF(AND(C2>0,C2<=100),"1",IF(AND(C2>100,C2<=300),"2",IF(AND(C2>300,C2<=600),"3",IF(AND(C2>600,C2<=1000),"4",IF(C2>1000,"5"))))) -> 1 | V2: =IF(T2<=0,"Planned",IF(AND(T2>0,T2<=5),"1",IF(AND(T2>5,T2<=10),"2",IF(AND(T2>10,T2<=15),"3",IF(AND(T2>15,T2<=20),"4",IF(AND(T2>20,T2<=25),"5",IF(AND(T2>25,T2<=30),"6",IF(AND(T2>30,T2<=35),"7",IF(AND(T2>35,T2<=40),"8",IF(T2>40,"9")))))))))) -> 1 | W2: PLN | X2: SubC | Y2: Stoker | AC2: -8.2417453 | AD2: 124.53197
B3: Alor Unit 2 | C3: 3 | D3: NA | E3: NA | F3: <30 MW | G3: Nusa Tenggara | H3: Yes | J3: =iferror(vlookup(vlookup(B3,'Co-firing inputs'!B:C,2,false),'Co-firing inputs'!B:G,6,false),"None") -> None | N3: planned | O3: planned | Q3: 2025 | T3: =YEAR(today())-Q3 -> 1 | U3: =IF(AND(C3>0,C3<=100),"1",IF(AND(C3>100,C3<=300),"2",IF(AND(C3>300,C3<=600),"3",IF(AND(C3>600,C3<=1000),"4",IF(C3>1000,"5"))))) -> 1 | V3: =IF(T3<=0,"Planned",IF(AND(T3>0,T3<=5),"1",IF(AND(T3>5,T3<=10),"2",IF(AND(T3>10,T3<=15),"3",IF(AND(T3>15,T3<=20),"4",IF(AND(T3>20,T3<=25),"5",IF(AND(T3>25,T3<=30),"6",IF(AND(T3>30,T3<=35),"7",IF(AND(T3>35,T3<=40),"8",IF(T3>40,"9")))))))))) -> 1 | W3: PLN | X3: SubC | Y3: Stoker | AC3: -8.2417453 | AD3: 124.53197
B4: Ampana Unit 1 | C4: 3 | D4: NA | E4: NA | F4: <30 MW | G4: Sulawesi | J4: Commercial/implemented | K4: Woodchip | L4: 0.05 | N4: operating | O4: operating | P4: operating | Q4: 2017 | T4: =YEAR(today())-Q4 -> 9 | U4: =IF(AND(C4>0,C4<=100),"1",IF(AND(C4>100,C4<=300),"2",IF(AND(C4>300,C4<=600),"3",IF(AND(C4>600,C4<=1000),"4",IF(C4>1000,"5"))))) -> 1 | V4: =IF(T4<=0,"Planned",IF(AND(T4>0,T4<=5),"1",IF(AND(T4>5,T4<=10),"2",IF(AND(T4>10,T4<=15),"3",IF(AND(T4>15,T4<=20),"4",IF(AND(T4>20,T4<=25),"5",IF(AND(T4>25,T4<=30),"6",IF(AND(T4>30,T4<=35),"7",IF(AND(T4>35,T4<=40),"8",IF(T4>40,"9")))))))))) -> 2 | W4: PLN | AC4: -0.96418417 | AD4: 121.82305
B5: Ampana Unit 2 | C5: 3 | D5: NA | E5: NA | F5: <30 MW | G5: Sulawesi | J5: Commercial/implemented | K5: Woodchip | L5: 0.05 | N5: operating | O5: operating | P5: operating | Q5: 2017 | T5: =YEAR(today())-Q5 -> 9 | U5: =IF(AND(C5>0,C5<=100),"1",IF(AND(C5>100,C5<=300),"2",IF(AND(C5>300,C5<=600),"3",IF(AND(C5>600,C5<=1000),"4",IF(C5>1000,"5"))))) -> 1 | V5: =IF(T5<=0,"Planned",IF(AND(T5>0,T5<=5),"1",IF(AND(T5>5,T5<=10),"2",IF(AND(T5>10,T5<=15),"3",IF(AND(T5>15,T5<=20),"4",IF(AND(T5>20,T5<=25),"5",IF(AND(T5>25,T5<=30),"6",IF(AND(T5>30,T5<=35),"7",IF(AND(T5>35,T5<=40),"8",IF(T5>40,"9")))))))))) -> 2 | W5: PLN | AC5: -0.96418417 | AD5: 121.82305
B6: Atambua Unit 1 | C6: 6 | D6: NA | E6: NA | F6: <30 MW | G6: Nusa Tenggara | H6: Yes | I6: Yes | J6: =iferror(vlookup(vlookup(B6,'Co-firing inputs'!B:C,2,false),'Co-firing inputs'!B:G,6,false),"None") -> None | N6: planned | O6: planned | Q6: 2027 | R6: 2030 | T6: =YEAR(today())-Q6 -> -1 | U6: =IF(AND(C6>0,C6<=100),"1",IF(AND(C6>100,C6<=300),"2",IF(AND(C6>300,C6<=600),"3",IF(AND(C6>600,C6<=1000),"4",IF(C6>1000,"5"))))) -> 1 | V6: =IF(T6<=0,"Planned",IF(AND(T6>0,T6<=5),"1",IF(AND(T6>5,T6<=10),"2",IF(AND(T6>10,T6<=15),"3",IF(AND(T6>15,T6<=20),"4",IF(AND(T6>20,T6<=25),"5",IF(AND(T6>25,T6<=30),"6",IF(AND(T6>30,T6<=35),"7",IF(AND(T6>35,T6<=40),"8",IF(T6>40,"9")))))))))) -> Planned | W6: PLN | X6: SubC | Y6: Stoker | AC6: -0.3730972 | AD6: 117.06246
B7: Atambua Unit 2 | C7: 6 | D7: NA | E7: NA | F7: <30 MW | G7: Nusa Tenggara | H7: Yes | I7: Yes | J7: =iferror(vlookup(vlookup(B7,'Co-firing inputs'!B:C,2,false),'Co-firing inputs'!B:G,6,false),"None") -> None | N7: planned | O7: planned | Q7: 2027 | R7: 2030 | T7: =YEAR(today())-Q7 -> -1 | U7: =IF(AND(C7>0,C7<=100),"1",IF(AND(C7>100,C7<=300),"2",IF(AND(C7>300,C7<=600),"3",IF(AND(C7>600,C7<=1000),"4",IF(C7>1000,"5"))))) -> 1 | V7: =IF(T7<=0,"Planned",IF(AND(T7>0,T7<=5),"1",IF(AND(T7>5,T7<=10),"2",IF(AND(T7>10,T7<=15),"3",IF(AND(T7>15,T7<=20),"4",IF(AND(T7>20,T7<=25),"5",IF(AND(T7>25,T7<=30),"6",IF(AND(T7>30,T7<=35),"7",IF(AND(T7>35,T7<=40),"8",IF(T7>40,"9")))))))))) -> Planned | W7: PLN | X7: SubC | Y7: Stoker | AC7: -0.3730972 | AD7: 117.06246
B8: Atambua Unit 3 | C8: 6 | D8: NA | E8: NA | F8: <30 MW | G8: Nusa Tenggara | H8: Yes | I8: Yes | J8: =iferror(vlookup(vlookup(B8,'Co-firing inputs'!B:C,2,false),'Co-firing inputs'!B:G,6,false),"None") -> None | N8: planned | O8: planned | Q8: 2027 | R8: 2030 | T8: =YEAR(today())-Q8 -> -1 | U8: =IF(AND(C8>0,C8<=100),"1",IF(AND(C8>100,C8<=300),"2",IF(AND(C8>300,C8<=600),"3",IF(AND(C8>600,C8<=1000),"4",IF(C8>1000,"5"))))) -> 1 | V8: =IF(T8<=0,"Planned",IF(AND(T8>0,T8<=5),"1",IF(AND(T8>5,T8<=10),"2",IF(AND(T8>10,T8<=15),"3",IF(AND(T8>15,T8<=20),"4",IF(AND(T8>20,T8<=25),"5",IF(AND(T8>25,T8<=30),"6",IF(AND(T8>30,T8<=35),"7",IF(AND(T8>35,T8<=40),"8",IF(T8>40,"9")))))))))) -> Planned | W8: PLN | X8: SubC | Y8: Stoker | AC8: -0.3730972 | AD8: 117.06246
B9: Atambua Unit 4 | C9: 6 | D9: NA | E9: NA | F9: <30 MW | G9: Nusa Tenggara | H9: Yes | I9: Yes | J9: =iferror(vlookup(vlookup(B9,'Co-firing inputs'!B:C,2,false),'Co-firing inputs'!B:G,6,false),"None") -> None | N9: planned | O9: planned | Q9: 2027 | R9: 2030 | T9: =YEAR(today())-Q9 -> -1 | U9: =IF(AND(C9>0,C9<=100),"1",IF(AND(C9>100,C9<=300),"2",IF(AND(C9>300,C9<=600),"3",IF(AND(C9>600,C9<=1000),"4",IF(C9>1000,"5"))))) -> 1 | V9: =IF(T9<=0,"Planned",IF(AND(T9>0,T9<=5),"1",IF(AND(T9>5,T9<=10),"2",IF(AND(T9>10,T9<=15),"3",IF(AND(T9>15,T9<=20),"4",IF(AND(T9>20,T9<=25),"5",IF(AND(T9>25,T9<=30),"6",IF(AND(T9>30,T9<=35),"7",IF(AND(T9>35,T9<=40),"8",IF(T9>40,"9")))))))))) -> Planned | W9: PLN | X9: SubC | Y9: Stoker | AC9: -0.3730972 | AD9: 117.06246
B10: Berau Unit 1 | C10: 7 | D10: NA | E10: NA | F10: <30 MW | G10: Kalimantan | J10: =iferror(vlookup(vlookup(B10,'Co-firing inputs'!B:C,2,false),'Co-firing inputs'!B:G,6,false),"None") -> Commercial/implemented | K10: Palm Kernel Shell | L10: 0.05 | N10: operating | O10: operating | P10: operating | Q10: 2020 | T10: =YEAR(today())-Q10 -> 6 | U10: =IF(AND(C10>0,C10<=100),"1",IF(AND(C10>100,C10<=300),"2",IF(AND(C10>300,C10<=600),"3",IF(AND(C10>600,C10<=1000),"4",IF(C10>1000,"5"))))) -> 1 | V10: =IF(T10<=0,"Planned",IF(AND(T10>0,T10<=5),"1",IF(AND(T10>5,T10<=10),"2",IF(AND(T10>10,T10<=15),"3",IF(AND(T10>15,T10<=20),"4",IF(AND(T10>20,T10<=25),"5",IF(AND(T10>25,T10<=30),"6",IF(AND(T10>30,T10<=35),"7",IF(AND(T10>35,T10<=40),"8",IF(T10>40,"9")))))))))) -> 2 | W10: PLN | X10: SubC | Y10: Stoker | AA10: ESP | AC10: 2.1567161 | AD10: 117.39229
B11: Berau Unit 2 | C11: 7 | D11: NA | E11: NA | F11: <30 MW | G11: Kalimantan | J11: =iferror(vlookup(vlookup(B11,'Co-firing inputs'!B:C,2,false),'Co-firing inputs'!B:G,6,false),"None") -> Commercial/implemented | K11: Palm Kernel Shell | L11: 0.05 | N11: operating | O11: operating | P11: operating | Q11: 2019 | T11: =YEAR(today())-Q11 -> 7 | U11: =IF(AND(C11>0,C11<=100),"1",IF(AND(C11>100,C11<=300),"2",IF(AND(C11>300,C11<=600),"3",IF(AND(C11>600,C11<=1000),"4",IF(C11>1000,"5"))))) -> 1 | V11: =IF(T11<=0,"Planned",IF(AND(T11>0,T11<=5),"1",IF(AND(T11>5,T11<=10),"2",IF(AND(T11>10,T11<=15),"3",IF(AND(T11>15,T11<=20),"4",IF(AND(T11>20,T11<=25),"5",IF(AND(T11>25,T11<=30),"6",IF(AND(T11>30,T11<=35),"7",IF(AND(T11>35,T11<=40),"8",IF(T11>40,"9")))))))))) -> 2 | W11: PLN | X11: SubC | Y11: Stoker | AA11: ESP | AC11: 2.1567161 | AD11: 117.39229
B12: Bima Unit 1 | C12: 10 | D12: NA | E12: NA | F12: <30 MW | G12: Nusa Tenggara | H12: Yes | J12: =iferror(vlookup(vlookup(B12,'Co-firing inputs'!B:C,2,false),'Co-firing inputs'!B:G,6,false),"None") -> None | M12: FTP-1 | N12: planned | O12: planned | Q12: 2029 | T12: =YEAR(today())-Q12 -> -3 | U12: =IF(AND(C12>0,C12<=100),"1",IF(AND(C12>100,C12<=300),"2",IF(AND(C12>300,C12<=600),"3",IF(AND(C12>600,C12<=1000),"4",IF(C12>1000,"5"))))) -> 1 | V12: =IF(T12<=0,"Planned",IF(AND(T12>0,T12<=5),"1",IF(AND(T12>5,T12<=10),"2",IF(AND(T12>10,T12<=15),"3",IF(AND(T12>15,T12<=20),"4",IF(AND(T12>20,T12<=25),"5",IF(AND(T12>25,T12<=30),"6",IF(AND(T12>30,T12<=35),"7",IF(AND(T12>35,T12<=40),"8",IF(T12>40,"9")))))))))) -> Planned | W12: PLN | X12: SubC | Y12: CFB | AC12: -8.4072501 | AD12: 118.69985
B13: Bima Unit 2 | C13: 10 | D13: NA | E13: NA | F13: <30 MW | G13: Nusa Tenggara | H13: Yes | J13: =iferror(vlookup(vlookup(B13,'Co-firing inputs'!B:C,2,false),'Co-firing inputs'!B:G,6,false),"None") -> None | M13: FTP-1 | N13: planned | O13: planned | Q13: 2029 | T13: =YEAR(today())-Q13 -> -3 | U13: =IF(AND(C13>0,C13<=100),"1",IF(AND(C13>100,C13<=300),"2",IF(AND(C13>300,C13<=600),"3",IF(AND(C13>600,C13<=1000),"4",IF(C13>1000,"5"))))) -> 1 | V13: =IF(T13<=0,"Planned",IF(AND(T13>0,T13<=5),"1",IF(AND(T13>5,T13<=10),"2",IF(AND(T13>10,T13<=15),"3",IF(AND(T13>15,T13<=20),"4",IF(AND(T13>20,T13<=25),"5",IF(AND(T13>25,T13<=30),"6",IF(AND(T13>30,T13<=35),"7",IF(AND(T13>35,T13<=40),"8",IF(T13>40,"9")))))))))) -> Planned | W13: PLN | X13: SubC | Y13: CFB | AC13: -8.4072501 | AD13: 118.69985
B14: Embalut Unit 1 | C14: 25 | D14: NA | E14: NA | F14: <30 MW | G14: Kalimantan | J14: =iferror(vlookup(vlookup(B14,'Co-firing inputs'!B:C,2,false),'Co-firing inputs'!B:G,6,false),"None") -> None | N14: operating | O14: operating | P14: operating | Q14: 2008 | T14: =YEAR(today())-Q14 -> 18 | U14: =IF(AND(C14>0,C14<=100),"1",IF(AND(C14>100,C14<=300),"2",IF(AND(C14>300,C14<=600),"3",IF(AND(C14>600,C14<=1000),"4",IF(C14>1000,"5"))))) -> 1 | V14: =IF(T14<=0,"Planned",IF(AND(T14>0,T14<=5),"1",IF(AND(T14>5,T14<=10),"2",IF(AND(T14>10,T14<=15),"3",IF(AND(T14>15,T14<=20),"4",IF(AND(T14>20,T14<=25),"5",IF(AND(T14>25,T14<=30),"6",IF(AND(T14>30,T14<=35),"7",IF(AND(T14>35,T14<=40),"8",IF(T14>40,"9")))))))))) -> 4 | W14: IPP | X14: SubC | Y14: PC | AC14: -0.3730972 | AD14: 117.06246
B15: Embalut Unit 2 | C15: 25 | D15: NA | E15: NA | F15: <30 MW | G15: Kalimantan | J15: =iferror(vlookup(vlookup(B15,'Co-firing inputs'!B:C,2,false),'Co-firing inputs'!B:G,6,false),"None") -> None | N15: operating | O15: operating | P15: operating | Q15: 2008 | T15: =YEAR(today())-Q15 -> 18 | U15: =IF(AND(C15>0,C15<=100),"1",IF(AND(C15>100,C15<=300),"2",IF(AND(C15>300,C15<=600),"3",IF(AND(C15>600,C15<=1000),"4",IF(C15>1000,"5"))))) -> 1 | V15: =IF(T15<=0,"Planned",IF(AND(T15>0,T15<=5),"1",IF(AND(T15>5,T15<=10),"2",IF(AND(T15>10,T15<=15),"3",IF(AND(T15>15,T15<=20),"4",IF(AND(T15>20,T15<=25),"5",IF(AND(T15>25,T15<=30),"6",IF(AND(T15>30,T15<=35),"7",IF(AND(T15>35,T15<=40),"8",IF(T15>40,"9")))))))))) -> 4 | W15: IPP | X15: SubC | Y15: PC | AC15: -0.3730972 | AD15: 117.06246
B16: Gorontalo Unit 1 | C16: 25 | D16: NA | E16: NA | F16: <30 MW | G16: Sulawesi | J16: =iferror(vlookup(vlookup(B16,'Co-firing inputs'!B:C,2,false),'Co-firing inputs'!B:G,6,false),"None") -> Commercial/implemented | K16: Woodchip & Sawdust | L16: 0.05 | N16: operating | O16: operating | P16: operating | Q16: 2020 | T16: =YEAR(today())-Q16 -> 6 | U16: =IF(AND(C16>0,C16<=100),"1",IF(AND(C16>100,C16<=300),"2",IF(AND(C16>300,C16<=600),"3",IF(AND(C16>600,C16<=1000),"4",IF(C16>1000,"5"))))) -> 1 | V16: =IF(T16<=0,"Planned",IF(AND(T16>0,T16<=5),"1",IF(AND(T16>5,T16<=10),"2",IF(AND(T16>10,T16<=15),"3",IF(AND(T16>15,T16<=20),"4",IF(AND(T16>20,T16<=25),"5",IF(AND(T16>25,T16<=30),"6",IF(AND(T16>30,T16<=35),"7",IF(AND(T16>35,T16<=40),"8",IF(T16>40,"9")))))))))) -> 2 | W16: PLN | X16: SubC | Y16: CFB | AA16: ESP, Cyclone, Limestone | AC16: 0.85051045 | AD16: 122.79643
B17: Gorontalo Unit 2 | C17: 25 | D17: NA | E17: NA | F17: <30 MW | G17: Sulawesi | J17: =iferror(vlookup(vlookup(B17,'Co-firing inputs'!B:C,2,false),'Co-firing inputs'!B:G,6,false),"None") -> Commercial/implemented | K17: Woodchip & Sawdust | L17: 0.05 | N17: operating | O17: operating | P17: operating | Q17: 2020 | T17: =YEAR(today())-Q17 -> 6 | U17: =IF(AND(C17>0,C17<=100),"1",IF(AND(C17>100,C17<=300),"2",IF(AND(C17>300,C17<=600),"3",IF(AND(C17>600,C17<=1000),"4",IF(C17>1000,"5"))))) -> 1 | V17: =IF(T17<=0,"Planned",IF(AND(T17>0,T17<=5),"1",IF(AND(T17>5,T17<=10),"2",IF(AND(T17>10,T17<=15),"3",IF(AND(T17>15,T17<=20),"4",IF(AND(T17>20,T17<=25),"5",IF(AND(T17>25,T17<=30),"6",IF(AND(T17>30,T17<=35),"7",IF(AND(T17>35,T17<=40),"8",IF(T17>40,"9")))))))))) -> 2 | W17: PLN | X17: SubC | Y17: CFB | AA17: ESP, Cyclone, Limestone | AC17: 0.85051045 | AD17: 122.79643
B18: Holtekamp Unit 1 | C18: 10 | D18: NA | E18: NA | F18: <30 MW | G18: Papua | J18: Commercial/implemented | K18: Woodchip | L18: NA | N18: operating | O18: operating | P18: operating | Q18: 2011 | T18: =YEAR(today())-Q18 -> 15 | U18: =IF(AND(C18>0,C18<=100),"1",IF(AND(C18>100,C18<=300),"2",IF(AND(C18>300,C18<=600),"3",IF(AND(C18>600,C18<=1000),"4",IF(C18>1000,"5"))))) -> 1 | V18: =IF(T18<=0,"Planned",IF(AND(T18>0,T18<=5),"1",IF(AND(T18>5,T18<=10),"2",IF(AND(T18>10,T18<=15),"3",IF(AND(T18>15,T18<=20),"4",IF(AND(T18>20,T18<=25),"5",IF(AND(T18>25,T18<=30),"6",IF(AND(T18>30,T18<=35),"7",IF(AND(T18>35,T18<=40),"8",IF(T18>40,"9")))))))))) -> 3 | W18: PLN | X18: SubC | Y18: Stoker | AA18: Dust Collector, Desulphuriser | AC18: -2.6143323 | AD18: 140.79049
B19: Holtekamp Unit 2 | C19: 10 | D19: NA | E19: NA | F19: <30 MW | G19: Papua | J19: Commercial/implemented | K19: Woodchip | L19: NA | N19: operating | O19: operating | P19: operating | Q19: 2011 | T19: =YEAR(today())-Q19 -> 15 | U19: =IF(AND(C19>0,C19<=100),"1",IF(AND(C19>100,C19<=300),"2",IF(AND(C19>300,C19<=600),"3",IF(AND(C19>600,C19<=1000),"4",IF(C19>1000,"5"))))) -> 1 | V19: =IF(T19<=0,"Planned",IF(AND(T19>0,T19<=5),"1",IF(AND(T19>5,T19<=10),"2",IF(AND(T19>10,T19<=15),"3",IF(AND(T19>15,T19<=20),"4",IF(AND(T19>20,T19<=25),"5",IF(AND(T19>25,T19<=30),"6",IF(AND(T19>30,T19<=35),"7",IF(AND(T19>35,T19<=40),"8",IF(T19>40,"9")))))))))) -> 3 | W19: PLN | X19: SubC | Y19: Stoker | AA19: Dust Collector, Desulphuriser | AC19: -2.6143323 | AD19: 140.79049
B20: Jeranjang Unit 1 | C20: 25 | D20: NA | E20: NA | F20: <30 MW | G20: Nusa Tenggara | J20: =iferror(vlookup(vlookup(B20,'Co-firing inputs'!B:C,2,false),'Co-firing inputs'!B:G,6,false),"None") -> Commercial/implemented | K20: Sawdust, Waste Pellet | L20: 0.03 | N20: operating | O20: operating | P20: operating | Q20: 2014 | T20: =YEAR(today())-Q20 -> 12 | U20: =IF(AND(C20>0,C20<=100),"1",IF(AND(C20>100,C20<=300),"2",IF(AND(C20>300,C20<=600),"3",IF(AND(C20>600,C20<=1000),"4",IF(C20>1000,"5"))))) -> 1 | V20: =IF(T20<=0,"Planned",IF(AND(T20>0,T20<=5),"1",IF(AND(T20>5,T20<=10),"2",IF(AND(T20>10,T20<=15),"3",IF(AND(T20>15,T20<=20),"4",IF(AND(T20>20,T20<=25),"5",IF(AND(T20>25,T20<=30),"6",IF(AND(T20>30,T20<=35),"7",IF(AND(T20>35,T20<=40),"8",IF(T20>40,"9")))))))))) -> 3 | W20: PLN | X20: SubC | Y20: CFB | AA20: ESP, Low NOx Burner | AC20: -8.6587616 | AD20: 116.07313 | AL20: 77.6
B21: Jeranjang Unit 2 | C21: 25 | D21: NA | E21: NA | F21: <30 MW | G21: Nusa Tenggara | J21: =iferror(vlookup(vlookup(B21,'Co-firing inputs'!B:C,2,false),'Co-firing inputs'!B:G,6,false),"None") -> Commercial/implemented | K21: Sawdust, Waste Pellet | L21: 0.03 | N21: operating | O21: operating | P21: operating | Q21: 2014 | T21: =YEAR(today())-Q21 -> 12 | U21: =IF(AND(C21>0,C21<=100),"1",IF(AND(C21>100,C21<=300),"2",IF(AND(C21>300,C21<=600),"3",IF(AND(C21>600,C21<=1000),"4",IF(C21>1000,"5"))))) -> 1 | V21: =IF(T21<=0,"Planned",IF(AND(T21>0,T21<=5),"1",IF(AND(T21>5,T21<=10),"2",IF(AND(T21>10,T21<=15),"3",IF(AND(T21>15,T21<=20),"4",IF(AND(T21>20,T21<=25),"5",IF(AND(T21>25,T21<=30),"6",IF(AND(T21>30,T21<=35),"7",IF(AND(T21>35,T21<=40),"8",IF(T21>40,"9")))))))))) -> 3 | W21: PLN | X21: SubC | Y21: CFB | AA21: ESP, Low NOx Burner | AC21: -8.6587616 | AD21: 116.07313 | AL21: 77.6
B22: Jeranjang Unit 3 | C22: 25 | D22: NA | E22: NA | F22: <30 MW | G22: Nusa Tenggara | J22: =iferror(vlookup(vlookup(B22,'Co-firing inputs'!B:C,2,false),'Co-firing inputs'!B:G,6,false),"None") -> Commercial/implemented | K22: Sawdust, Waste Pellet | L22: 0.03 | N22: operating | O22: operating | P22: operating | Q22: 2014 | T22: =YEAR(today())-Q22 -> 12 | U22: =IF(AND(C22>0,C22<=100),"1",IF(AND(C22>100,C22<=300),"2",IF(AND(C22>300,C22<=600),"3",IF(AND(C22>600,C22<=1000),"4",IF(C22>1000,"5"))))) -> 1 | V22: =IF(T22<=0,"Planned",IF(AND(T22>0,T22<=5),"1",IF(AND(T22>5,T22<=10),"2",IF(AND(T22>10,T22<=15),"3",IF(AND(T22>15,T22<=20),"4",IF(AND(T22>20,T22<=25),"5",IF(AND(T22>25,T22<=30),"6",IF(AND(T22>30,T22<=35),"7",IF(AND(T22>35,T22<=40),"8",IF(T22>40,"9")))))))))) -> 3 | W22: PLN | X22: SubC | Y22: CFB | AA22: ESP, Low NOx Burner | AB22: 16/8/24 - new entry, Jeranjang, 3x25MW, https://www.rri.co.id/bisnis/529070/dukung-nze-2050-pt-pba-komitmen-penuhi-biomassa-pltu-jeranjang | AC22: -8.6587616 | AD22: 116.07313 | AL22: 77.6
A23: Priority | B23: Kaltim (MT) Unit 1 | C23: 27.5 | D23: NA | E23: NA | F23: <30 MW | G23: Kalimantan | J23: =iferror(vlookup(vlookup(B23,'Co-firing inputs'!B:C,2,false),'Co-firing inputs'!B:G,6,false),"None") -> None | N23: operating | O23: operating | P23: operating | Q23: 2018 | T23: =YEAR(today())-Q23 -> 8 | U23: =IF(AND(C23>0,C23<=100),"1",IF(AND(C23>100,C23<=300),"2",IF(AND(C23>300,C23<=600),"3",IF(AND(C23>600,C23<=1000),"4",IF(C23>1000,"5"))))) -> 1 | V23: =IF(T23<=0,"Planned",IF(AND(T23>0,T23<=5),"1",IF(AND(T23>5,T23<=10),"2",IF(AND(T23>10,T23<=15),"3",IF(AND(T23>15,T23<=20),"4",IF(AND(T23>20,T23<=25),"5",IF(AND(T23>25,T23<=30),"6",IF(AND(T23>30,T23<=35),"7",IF(AND(T23>35,T23<=40),"8",IF(T23>40,"9")))))))))) -> 2 | W23: IPP | X23: SubC-MM | Y23: CFB | AB23: PLTU Muara Jawa - Kutai Kartanegara, Kalimantan Timur | AC23: -0.77860264 | AD23: 117.18886
B24: Kaltim (MT) Unit 2 | C24: 27.5 | D24: NA | E24: NA | F24: <30 MW | G24: Kalimantan | J24: =iferror(vlookup(vlookup(B24,'Co-firing inputs'!B:C,2,false),'Co-firing inputs'!B:G,6,false),"None") -> None | N24: operating | O24: operating | P24: operating | Q24: 2018 | T24: =YEAR(today())-Q24 -> 8 | U24: =IF(AND(C24>0,C24<=100),"1",IF(AND(C24>100,C24<=300),"2",IF(AND(C24>300,C24<=600),"3",IF(AND(C24>600,C24<=1000),"4",IF(C24>1000,"5"))))) -> 1 | V24: =IF(T24<=0,"Planned",IF(AND(T24>0,T24<=5),"1",IF(AND(T24>5,T24<=10),"2",IF(AND(T24>10,T24<=15),"3",IF(AND(T24>15,T24<=20),"4",IF(AND(T24>20,T24<=25),"5",IF(AND(T24>25,T24<=30),"6",IF(AND(T24>30,T24<=35),"7",IF(AND(T24>35,T24<=40),"8",IF(T24>40,"9")))))))))) -> 2 | W24: IPP | X24: SubC-MM | Y24: CFB | AB24: PLTU Muara Jawa - Kutai Kartanegara, Kalimantan Timur | AC24: -0.77860264 | AD24: 117.18886
B25: Ketapang Unit 1 | C25: 10 | D25: NA | E25: NA | F25: <30 MW | G25: Kalimantan | J25: =iferror(vlookup(vlookup(B25,'Co-firing inputs'!B:C,2,false),'Co-firing inputs'!B:G,6,false),"None") -> Commercial/implemented | K25: Palm Kernel Shell | L25: 0.05 | N25: operating | O25: operating | P25: operating | Q25: 2016 | T25: =YEAR(today())-Q25 -> 10 | U25: =IF(AND(C25>0,C25<=100),"1",IF(AND(C25>100,C25<=300),"2",IF(AND(C25>300,C25<=600),"3",IF(AND(C25>600,C25<=1000),"4",IF(C25>1000,"5"))))) -> 1 | V25: =IF(T25<=0,"Planned",IF(AND(T25>0,T25<=5),"1",IF(AND(T25>5,T25<=10),"2",IF(AND(T25>10,T25<=15),"3",IF(AND(T25>15,T25<=20),"4",IF(AND(T25>20,T25<=25),"5",IF(AND(T25>25,T25<=30),"6",IF(AND(T25>30,T25<=35),"7",IF(AND(T25>35,T25<=40),"8",IF(T25>40,"9")))))))))) -> 2 | W25: PLN | X25: SubC | Y25: CFB | AA25: ESP, Low NOx Burner, Limestone | AC25: -1.7800852 | AD25: 109.94267 | AL25: 63.4
A26: AMDAL on hand | B26: Ketapang Unit 2 | C26: 10 | D26: NA | E26: NA | F26: <30 MW | G26: Kalimantan | J26: =iferror(vlookup(vlookup(B26,'Co-firing inputs'!B:C,2,false),'Co-firing inputs'!B:G,6,false),"None") -> Commercial/implemented | K26: Palm Kernel Shell | L26: 0.05 | N26: operating | O26: operating | P26: operating | Q26: 2016 | T26: =YEAR(today())-Q26 -> 10 | U26: =IF(AND(C26>0,C26<=100),"1",IF(AND(C26>100,C26<=300),"2",IF(AND(C26>300,C26<=600),"3",IF(AND(C26>600,C26<=1000),"4",IF(C26>1000,"5"))))) -> 1 | V26: =IF(T26<=0,"Planned",IF(AND(T26>0,T26<=5),"1",IF(AND(T26>5,T26<=10),"2",IF(AND(T26>10,T26<=15),"3",IF(AND(T26>15,T26<=20),"4",IF(AND(T26>20,T26<=25),"5",IF(AND(T26>25,T26<=30),"6",IF(AND(T26>30,T26<=35),"7",IF(AND(T26>35,T26<=40),"8",IF(T26>40,"9")))))))))) -> 2 | W26: PLN | X26: SubC | Y26: CFB | AA26: ESP, Limestone | AC26: -1.7800852 | AD26: 109.94267 | AL26: 63.4
A27: AMDAL on hand | B27: Kotabaru Unit 1 | C27: 7 | D27: NA | E27: NA | F27: <30 MW | G27: Kalimantan | H27: Yes | I27: Yes | J27: =iferror(vlookup(vlookup(B27,'Co-firing inputs'!B:C,2,false),'Co-firing inputs'!B:G,6,false),"None") -> None | N27: planned | O27: planned | Q27: 2025 | R27: 2030 | T27: =YEAR(today())-Q27 -> 1 | U27: =IF(AND(C27>0,C27<=100),"1",IF(AND(C27>100,C27<=300),"2",IF(AND(C27>300,C27<=600),"3",IF(AND(C27>600,C27<=1000),"4",IF(C27>1000,"5"))))) -> 1 | V27: =IF(T27<=0,"Planned",IF(AND(T27>0,T27<=5),"1",IF(AND(T27>5,T27<=10),"2",IF(AND(T27>10,T27<=15),"3",IF(AND(T27>15,T27<=20),"4",IF(AND(T27>20,T27<=25),"5",IF(AND(T27>25,T27<=30),"6",IF(AND(T27>30,T27<=35),"7",IF(AND(T27>35,T27<=40),"8",IF(T27>40,"9")))))))))) -> 1 | W27: PLN | X27: SubC | Y27: Stoker | AC27: -3.21269 | AD27: 116.25666
B28: Kotabaru Unit 2 | C28: 7 | D28: NA | E28: NA | F28: <30 MW | G28: Kalimantan | H28: Yes | I28: Yes | J28: =iferror(vlookup(vlookup(B28,'Co-firing inputs'!B:C,2,false),'Co-firing inputs'!B:G,6,false),"None") -> None | N28: planned | O28: planned | Q28: 2025 | R28: 2030 | T28: =YEAR(today())-Q28 -> 1 | U28: =IF(AND(C28>0,C28<=100),"1",IF(AND(C28>100,C28<=300),"2",IF(AND(C28>300,C28<=600),"3",IF(AND(C28>600,C28<=1000),"4",IF(C28>1000,"5"))))) -> 1 | V28: =IF(T28<=0,"Planned",IF(AND(T28>0,T28<=5),"1",IF(AND(T28>5,T28<=10),"2",IF(AND(T28>10,T28<=15),"3",IF(AND(T28>15,T28<=20),"4",IF(AND(T28>20,T28<=25),"5",IF(AND(T28>25,T28<=30),"6",IF(AND(T28>30,T28<=35),"7",IF(AND(T28>35,T28<=40),"8",IF(T28>40,"9")))))))))) -> 1 | W28: PLN | X28: SubC | Y28: Stoker | AC28: -3.21269 | AD28: 116.25666
B29: Kupang Baru Unit 1 | C29: 15 | D29: NA | E29: NA | F29: <30 MW | G29: Nusa Tenggara | I29: Yes | J29: Commercial/implemented | K29: Woodchip | L29: 0.05 | Q29: 2025 | R29: 2025 | T29: =YEAR(today())-Q29 -> 1 | U29: =IF(AND(C29>0,C29<=100),"1",IF(AND(C29>100,C29<=300),"2",IF(AND(C29>300,C29<=600),"3",IF(AND(C29>600,C29<=1000),"4",IF(C29>1000,"5"))))) -> 1 | V29: =IF(T29<=0,"Planned",IF(AND(T29>0,T29<=5),"1",IF(AND(T29>5,T29<=10),"2",IF(AND(T29>10,T29<=15),"3",IF(AND(T29>15,T29<=20),"4",IF(AND(T29>20,T29<=25),"5",IF(AND(T29>25,T29<=30),"6",IF(AND(T29>30,T29<=35),"7",IF(AND(T29>35,T29<=40),"8",IF(T29>40,"9")))))))))) -> 1 | W29: PLN | AC29: -10.239014 | AD29: 123.49016
B30: Kupang Baru Unit 2 | C30: 15 | D30: NA | E30: NA | F30: <30 MW | G30: Nusa Tenggara | I30: Yes | J30: Commercial/implemented | K30: Woodchip | L30: 0.05 | Q30: 2025 | R30: 2025 | T30: =YEAR(today())-Q30 -> 1 | U30: =IF(AND(C30>0,C30<=100),"1",IF(AND(C30>100,C30<=300),"2",IF(AND(C30>300,C30<=600),"3",IF(AND(C30>600,C30<=1000),"4",IF(C30>1000,"5"))))) -> 1 | V30: =IF(T30<=0,"Planned",IF(AND(T30>0,T30<=5),"1",IF(AND(T30>5,T30<=10),"2",IF(AND(T30>10,T30<=15),"3",IF(AND(T30>15,T30<=20),"4",IF(AND(T30>20,T30<=25),"5",IF(AND(T30>25,T30<=30),"6",IF(AND(T30>30,T30<=35),"7",IF(AND(T30>35,T30<=40),"8",IF(T30>40,"9")))))))))) -> 1 | W30: PLN | AC30: -10.239014 | AD30: 123.49016
B31: Kupang Unit 1 | C31: 16.5 | D31: NA | E31: NA | F31: <30 MW | G31: Nusa Tenggara | J31: =iferror(vlookup(vlookup(B31,'Co-firing inputs'!B:C,2,false),'Co-firing inputs'!B:G,6,false),"None") -> Commercial/implemented | K31: Woodchip | L31: 0.05 | M31: FTP-1 | N31: operating | O31: operating | P31: operating | Q31: 2013 | T31: =YEAR(today())-Q31 -> 13 | U31: =IF(AND(C31>0,C31<=100),"1",IF(AND(C31>100,C31<=300),"2",IF(AND(C31>300,C31<=600),"3",IF(AND(C31>600,C31<=1000),"4",IF(C31>1000,"5"))))) -> 1 | V31: =IF(T31<=0,"Planned",IF(AND(T31>0,T31<=5),"1",IF(AND(T31>5,T31<=10),"2",IF(AND(T31>10,T31<=15),"3",IF(AND(T31>15,T31<=20),"4",IF(AND(T31>20,T31<=25),"5",IF(AND(T31>25,T31<=30),"6",IF(AND(T31>30,T31<=35),"7",IF(AND(T31>35,T31<=40),"8",IF(T31>40,"9")))))))))) -> 3 | W31: PLN | X31: SubC | Y31: CFB | AA31: ESP | AC31: -10.238914 | AD31: 123.49026 | AL31: 50.75
B32: Kupang Unit 2 | C32: 16.5 | D32: NA | E32: NA | F32: <30 MW | G32: Nusa Tenggara | J32: =iferror(vlookup(vlookup(B32,'Co-firing inputs'!B:C,2,false),'Co-firing inputs'!B:G,6,false),"None") -> Commercial/implemented | K32: Woodchip | L32: 0.05 | M32: FTP-1 | N32: operating | O32: operating | P32: operating | Q32: 2013 | T32: =YEAR(today())-Q32 -> 13 | U32: =IF(AND(C32>0,C32<=100),"1",IF(AND(C32>100,C32<=300),"2",IF(AND(C32>300,C32<=600),"3",IF(AND(C32>600,C32<=1000),"4",IF(C32>1000,"5"))))) -> 1 | V32: =IF(T32<=0,"Planned",IF(AND(T32>0,T32<=5),"1",IF(AND(T32>5,T32<=10),"2",IF(AND(T32>10,T32<=15),"3",IF(AND(T32>15,T32<=20),"4",IF(AND(T32>20,T32<=25),"5",IF(AND(T32>25,T32<=30),"6",IF(AND(T32>30,T32<=35),"7",IF(AND(T32>35,T32<=40),"8",IF(T32>40,"9")))))))))) -> 3 | W32: PLN | X32: SubC | Y32: CFB | AA32: ESP | AC32: -10.238914 | AD32: 123.49026 | AL32: 50.75
B33: Lati Unit 1 | C33: 7 | D33: NA | E33: NA | F33: <30 MW | G33: Kalimantan | J33: =iferror(vlookup(vlookup(B33,'Co-firing inputs'!B:C,2,false),'Co-firing inputs'!B:G,6,false),"None") -> None | N33: operating | O33: operating | P33: operating | Q33: 2004 | T33: =YEAR(today())-Q33 -> 22 | U33: =IF(AND(C33>0,C33<=100),"1",IF(AND(C33>100,C33<=300),"2",IF(AND(C33>300,C33<=600),"3",IF(AND(C33>600,C33<=1000),"4",IF(C33>1000,"5"))))) -> 1 | V33: =IF(T33<=0,"Planned",IF(AND(T33>0,T33<=5),"1",IF(AND(T33>5,T33<=10),"2",IF(AND(T33>10,T33<=15),"3",IF(AND(T33>15,T33<=20),"4",IF(AND(T33>20,T33<=25),"5",IF(AND(T33>25,T33<=30),"6",IF(AND(T33>30,T33<=35),"7",IF(AND(T33>35,T33<=40),"8",IF(T33>40,"9")))))))))) -> 5 | W33: IPP | X33: SubC | Y33: Stoker | AC33: 2.2149949 | AD33: 117.61913
B34: Lati Unit 2 | C34: 7 | D34: NA | E34: NA | F34: <30 MW | G34: Kalimantan | J34: =iferror(vlookup(vlookup(B34,'Co-firing inputs'!B:C,2,false),'Co-firing inputs'!B:G,6,false),"None") -> None | N34: operating | O34: operating | P34: operating | Q34: 2004 | T34: =YEAR(today())-Q34 -> 22 | U34: =IF(AND(C34>0,C34<=100),"1",IF(AND(C34>100,C34<=300),"2",IF(AND(C34>300,C34<=600),"3",IF(AND(C34>600,C34<=1000),"4",IF(C34>1000,"5"))))) -> 1 | V34: =IF(T34<=0,"Planned",IF(AND(T34>0,T34<=5),"1",IF(AND(T34>5,T34<=10),"2",IF(AND(T34>10,T34<=15),"3",IF(AND(T34>15,T34<=20),"4",IF(AND(T34>20,T34<=25),"5",IF(AND(T34>25,T34<=30),"6",IF(AND(T34>30,T34<=35),"7",IF(AND(T34>35,T34<=40),"8",IF(T34>40,"9")))))))))) -> 5 | W34: IPP | X34: SubC | Y34: Stoker | AC34: 2.2149949 | AD34: 117.61913
B35: Lati Unit 3 | C35: 7 | D35: NA | E35: NA | F35: <30 MW | G35: Kalimantan | J35: =iferror(vlookup(vlookup(B35,'Co-firing inputs'!B:C,2,false),'Co-firing inputs'!B:G,6,false),"None") -> None | N35: operating | O35: operating | P35: operating | Q35: 2004 | T35: =YEAR(today())-Q35 -> 22 | U35: =IF(AND(C35>0,C35<=100),"1",IF(AND(C35>100,C35<=300),"2",IF(AND(C35>300,C35<=600),"3",IF(AND(C35>600,C35<=1000),"4",IF(C35>1000,"5"))))) -> 1 | V35: =IF(T35<=0,"Planned",IF(AND(T35>0,T35<=5),"1",IF(AND(T35>5,T35<=10),"2",IF(AND(T35>10,T35<=15),"3",IF(AND(T35>15,T35<=20),"4",IF(AND(T35>20,T35<=25),"5",IF(AND(T35>25,T35<=30),"6",IF(AND(T35>30,T35<=35),"7",IF(AND(T35>35,T35<=40),"8",IF(T35>40,"9")))))))))) -> 5 | W35: IPP | X35: SubC | Y35: Stoker | AC35: 2.2149949 | AD35: 117.61913
A36: AMDAL on hand | B36: Lombok Timur Unit 1 | C36: 25 | D36: NA | E36: NA | F36: <30 MW | G36: Nusa Tenggara | J36: =iferror(vlookup(vlookup(B36,'Co-firing inputs'!B:C,2,false),'Co-firing inputs'!B:G,6,false),"None") -> None | N36: operating | O36: operating | P36: operating | Q36: 2017 | T36: =YEAR(today())-Q36 -> 9 | U36: =IF(AND(C36>0,C36<=100),"1",IF(AND(C36>100,C36<=300),"2",IF(AND(C36>300,C36<=600),"3",IF(AND(C36>600,C36<=1000),"4",IF(C36>1000,"5"))))) -> 1 | V36: =IF(T36<=0,"Planned",IF(AND(T36>0,T36<=5),"1",IF(AND(T36>5,T36<=10),"2",IF(AND(T36>10,T36<=15),"3",IF(AND(T36>15,T36<=20),"4",IF(AND(T36>20,T36<=25),"5",IF(AND(T36>25,T36<=30),"6",IF(AND(T36>30,T36<=35),"7",IF(AND(T36>35,T36<=40),"8",IF(T36>40,"9")))))))))) -> 2 | W36: IPP | X36: SubC | Y36: CFB | AB36: Location: Desa Padak Guar, Kelurahan Labuan Pandan, Kecamatan Sambelia, Kabupaten Lombok Timur, Provinsi Nusa Tenggara Barat | AC36: -8.4349475 | AD36: 116.70507 | AQ36: https://web.pln.co.id/cms/media/siaran-pers/2013/07/pln-tandatangani-perjanjian-jual-beli-listrik-pltu-lombok-timur-dengan-pt-lombok-energy-dynamics/
A37: AMDAL on hand | B37: Lombok Timur Unit 2 | C37: 25 | D37: NA | E37: NA | F37: <30 MW | G37: Nusa Tenggara | J37: =iferror(vlookup(vlookup(B37,'Co-firing inputs'!B:C,2,false),'Co-firing inputs'!B:G,6,false),"None") -> None | N37: operating | O37: operating | P37: operating | Q37: 2017 | T37: =YEAR(today())-Q37 -> 9 | U37: =IF(AND(C37>0,C37<=100),"1",IF(AND(C37>100,C37<=300),"2",IF(AND(C37>300,C37<=600),"3",IF(AND(C37>600,C37<=1000),"4",IF(C37>1000,"5"))))) -> 1 | V37: =IF(T37<=0,"Planned",IF(AND(T37>0,T37<=5),"1",IF(AND(T37>5,T37<=10),"2",IF(AND(T37>10,T37<=15),"3",IF(AND(T37>15,T37<=20),"4",IF(AND(T37>20,T37<=25),"5",IF(AND(T37>25,T37<=30),"6",IF(AND(T37>30,T37<=35),"7",IF(AND(T37>35,T37<=40),"8",IF(T37>40,"9")))))))))) -> 2 | W37: IPP | X37: SubC | Y37: CFB | AB37: Location: Desa Padak Guar, Kelurahan Labuan Pandan, Kecamatan Sambelia, Kabupaten Lombok Timur, Provinsi Nusa Tenggara Barat | AC37: -8.4349475 | AD37: 116.70507
A38: AMDAL on hand | B38: Malinau Unit 1 | C38: 3 | D38: NA | E38: NA | F38: <30 MW | G38: Kalimantan | H38: Yes | J38: Commercial/implemented | K38: Palm Kernel Shell | L38: NA | N38: construction | O38: operating | P38: operating | Q38: 2021 | T38: =YEAR(today())-Q38 -> 5 | U38: =IF(AND(C38>0,C38<=100),"1",IF(AND(C38>100,C38<=300),"2",IF(AND(C38>300,C38<=600),"3",IF(AND(C38>600,C38<=1000),"4",IF(C38>1000,"5"))))) -> 1 | V38: =IF(T38<=0,"Planned",IF(AND(T38>0,T38<=5),"1",IF(AND(T38>5,T38<=10),"2",IF(AND(T38>10,T38<=15),"3",IF(AND(T38>15,T38<=20),"4",IF(AND(T38>20,T38<=25),"5",IF(AND(T38>25,T38<=30),"6",IF(AND(T38>30,T38<=35),"7",IF(AND(T38>35,T38<=40),"8",IF(T38>40,"9")))))))))) -> 1 | W38: PLN | X38: SubC | Y38: Stoker | AC38: 3.6363153 | AD38: 116.67169
B39: Malinau Unit 2 | C39: 3 | D39: NA | E39: NA | F39: <30 MW | G39: Kalimantan | H39: Yes | J39: Commercial/implemented | K39: Palm Kernel Shell | L39: NA | N39: construction | O39: operating | P39: operating | Q39: 2021 | T39: =YEAR(today())-Q39 -> 5 | U39: =IF(AND(C39>0,C39<=100),"1",IF(AND(C39>100,C39<=300),"2",IF(AND(C39>300,C39<=600),"3",IF(AND(C39>600,C39<=1000),"4",IF(C39>1000,"5"))))) -> 1 | V39: =IF(T39<=0,"Planned",IF(AND(T39>0,T39<=5),"1",IF(AND(T39>5,T39<=10),"2",IF(AND(T39>10,T39<=15),"3",IF(AND(T39>15,T39<=20),"4",IF(AND(T39>20,T39<=25),"5",IF(AND(T39>25,T39<=30),"6",IF(AND(T39>30,T39<=35),"7",IF(AND(T39>35,T39<=40),"8",IF(T39>40,"9")))))))))) -> 1 | W39: PLN | X39: SubC | Y39: Stoker | AC39: 3.6363153 | AD39: 116.67169
B40: Mamuju Unit 1 | C40: 25 | D40: NA | E40: NA | F40: <30 MW | G40: Sulawesi | J40: =iferror(vlookup(vlookup(B40,'Co-firing inputs'!B:C,2,false),'Co-firing inputs'!B:G,6,false),"None") -> None | N40: operating | O40: operating | P40: operating | Q40: 2018 | T40: =YEAR(today())-Q40 -> 8 | U40: =IF(AND(C40>0,C40<=100),"1",IF(AND(C40>100,C40<=300),"2",IF(AND(C40>300,C40<=600),"3",IF(AND(C40>600,C40<=1000),"4",IF(C40>1000,"5"))))) -> 1 | V40: =IF(T40<=0,"Planned",IF(AND(T40>0,T40<=5),"1",IF(AND(T40>5,T40<=10),"2",IF(AND(T40>10,T40<=15),"3",IF(AND(T40>15,T40<=20),"4",IF(AND(T40>20,T40<=25),"5",IF(AND(T40>25,T40<=30),"6",IF(AND(T40>30,T40<=35),"7",IF(AND(T40>35,T40<=40),"8",IF(T40>40,"9")))))))))) -> 2 | W40: IPP | X40: SubC | Y40: CFB | AC40: -2.4724046 | AD40: 119.14687
...

Sheet Captive
A1: GEM Wiki | B1: CFPP name | C1: GEM unit/phase ID | D1: GEM ID | E1: Owner | F1: Captive industry | G1: Capacity (MW) | H1: COD | I1: Status Jul 2026 | J1: Status Jul 2024 | K1: Status Jan 2024 | L1: Status Jun 2023 | M1: Latitude | N1: Longitude | O1: Parent | P1: Province_EN | Q1: Provinsi_ID | R1: RUKN_out Mar 2025_new?
A2: https://www.gem.wiki/PT_IHIP_power_station | B2: PT IHIP Expansion Unit | C2: G100001053834 | D2: (new entry) | E2: Captive | F2: Industrial park | G2: 100 | I2: announced | M2: -2.2578515 | N2: 121.76902 | O2: Huakai Investment Co Ltd; Tongxiang Wushi Trading Co Ltd; unknown; Zhenshi Holding Group Co Ltd | P2: Central Sulawesi | Q2: Sulawesi Tengah | R2: yes
A3: https://www.gem.wiki/Hongshi_Silikon_power_station | B3: Hongshi Silikon | C3: G100001054115 | D3: (new entry) | E3: Captive | F3: Industrial park | G3: 2000 | I3: announced | M3: -6.87203 | N3: 107.59869 | O3: Hongshi Holding Group Co Ltd [100.0%] | P3: West Java | Q3: Jawa Barat | R3: yes
A4: https://www.gem.wiki/AlamTri_Aluminum_Smelter_power_station | B4: AlamTri Aluminum Smelter Phase II Unit 2 | C4: G100001092190 | D4: (new entry) | E4: Captive | F4: Aluminum | G4: 150 | H4: 2026 | I4: announced | M4: 2.4946822 | N4: 117.9002 | O4: PT Alamtri Resources Indonesia Tbk [84.0%]; PT Cita Mineral Investindo Tbk [16.0%] | P4: North Kalimantan | Q4: Kalimantan Utara | R4: yes
A5: https://www.gem.wiki/AlamTri_Aluminum_Smelter_power_station | B5: AlamTri Aluminum Smelter Phase II Unit 3 | C5: G100001092191 | D5: (new entry) | E5: Captive | F5: Aluminum | G5: 380 | H5: 2026 | I5: announced | M5: 2.4946822 | N5: 117.9002 | O5: PT Alamtri Resources Indonesia Tbk [84.0%]; PT Cita Mineral Investindo Tbk [16.0%] | P5: North Kalimantan | Q5: Kalimantan Utara | R5: yes
A6: https://www.gem.wiki/AlamTri_Aluminum_Smelter_power_station | B6: AlamTri Aluminum Smelter Phase II Unit 4 | C6: G100001092192 | D6: (new entry) | E6: Captive | F6: Aluminum | G6: 380 | H6: 2026 | I6: announced | M6: 2.4946822 | N6: 117.9002 | O6: PT Alamtri Resources Indonesia Tbk [84.0%]; PT Cita Mineral Investindo Tbk [16.0%] | P6: North Kalimantan | Q6: Kalimantan Utara | R6: yes
A7: https://www.gem.wiki/Nanshan_Industrial_Park_power_station | B7: Nanshan Industrial Park Phase II Unit 7 | C7: G100001093525 | D7: (new entry) | E7: Captive | F7: Aluminum | G7: 150 | H7: 2027 | I7: announced | M7: 0.911643 | N7: 104.65054 | O7: Nanshan Aluminium International Holdings Ltd [72.7%]; Hong Kong Prime Aluminium Investment Ltd [25.0%]; small shareholder(s) [2.3%] | P7: Riau Islands | Q7: Kepulauan Riau | R7: yes
A8: https://www.gem.wiki/Delong_Nickel_Phase_IV_power_station | B8: Delong Nickel Phase IV Unit 2 | C8: G100001031228 | D8: (new entry) | E8: Captive | F8: Nickel | G8: 330 | I8: construction | M8: -2.0165661 | N8: 121.43118 | O8: Zhongwei Hong Kong Zhengbang New Energy Co Ltd [35.0%]; Jiangsu Delong Nickel Industry Co Ltd [33.0%]; Zhongwei Hong Kong Zhenghong New Energy Co Ltd [25.0%]; Tongren Zhongwei Hongling No. 1 Enterprise Management Consulting Partnership LP [7.0%] | P8: Central Sulawesi | Q8: Sulawesi Tengah | R8: yes
A9: https://www.gem.wiki/AlamTri_Aluminum_Smelter_power_station | B9: AlamTri Aluminum Smelter Phase I Unit 2 | C9: G100001052602 | D9: (new entry) | E9: Captive | F9: Aluminum | G9: 150 | H9: 2026 | I9: construction | M9: 2.4946822 | N9: 117.9002 | O9: PT Alamtri Resources Indonesia Tbk [84.0%]; PT Cita Mineral Investindo Tbk [16.0%] | P9: North Kalimantan | Q9: Kalimantan Utara | R9: yes
A10: https://www.gem.wiki/AlamTri_Aluminum_Smelter_power_station | B10: AlamTri Aluminum Smelter Phase I Unit 3 | C10: G100001052603 | D10: (new entry) | E10: Captive | F10: Aluminum | G10: 380 | H10: 2025 | I10: construction | M10: 2.4946822 | N10: 117.9002 | O10: PT Alamtri Resources Indonesia Tbk [84.0%]; PT Cita Mineral Investindo Tbk [16.0%] | P10: North Kalimantan | Q10: Kalimantan Utara | R10: yes
A11: https://www.gem.wiki/AlamTri_Aluminum_Smelter_power_station | B11: AlamTri Aluminum Smelter Phase I Unit 4 | C11: G100001052604 | D11: (new entry) | E11: Captive | F11: Aluminum | G11: 380 | H11: 2025 | I11: construction | M11: 2.4946822 | N11: 117.9002 | O11: PT Alamtri Resources Indonesia Tbk [84.0%]; PT Cita Mineral Investindo Tbk [16.0%] | P11: North Kalimantan | Q11: Kalimantan Utara | R11: yes
A12: https://www.gem.wiki/Gallant_Venture_power_station | B12: Gallant Venture Phase I Unit 1 | C12: G100001054770 | D12: (new entry) | E12: Captive | F12: Industrial park | G12: 350 | I12: construction | M12: 0.9575588 | N12: 104.04864 | O12: Gallant Venture Ltd [100.0%] | P12: Riau Islands | Q12: Kepulauan Riau | R12: yes
A13: https://www.gem.wiki/Gallant_Venture_power_station | B13: Gallant Venture Phase I Unit 2 | C13: G100001054771 | D13: (new entry) | E13: Captive | F13: Industrial park | G13: 350 | I13: construction | M13: 0.9575588 | N13: 104.04864 | O13: Gallant Venture Ltd [100.0%] | P13: Riau Islands | Q13: Kepulauan Riau | R13: yes
A14: https://www.gem.wiki/Gallant_Venture_power_station | B14: Gallant Venture Phase I Unit 3 | C14: G100001054774 | D14: (new entry) | E14: Captive | F14: Industrial park | G14: 350 | I14: construction | M14: 0.9575588 | N14: 104.04864 | O14: Gallant Venture Ltd [100.0%] | P14: Riau Islands | Q14: Kepulauan Riau | R14: yes
A15: https://www.gem.wiki/Sulawesi_Labota_power_station | B15: Sulawesi Labota Unit 10 | C15: G100001093520 | D15: (new entry) | E15: Captive | F15: Aluminum, nickel | G15: 380 | H15: 2025 | I15: construction | M15: -2.87427 | N15: 122.1777 | O15: Huafon Group Co Ltd [65.0%]; Eternal Tsingshan Group Ltd [35.0%] | P15: Central Sulawesi | Q15: Sulawesi Tengah | R15: yes
A16: https://www.gem.wiki/Sulawesi_Labota_power_station | B16: Sulawesi Labota Unit 11 | C16: G100001093521 | D16: (new entry) | E16: Captive | F16: Aluminum, nickel | G16: 380 | H16: 2025 | I16: construction | M16: -2.87427 | N16: 122.1777 | O16: Huafon Group Co Ltd [65.0%]; Eternal Tsingshan Group Ltd [35.0%] | P16: Central Sulawesi | Q16: Sulawesi Tengah | R16: yes
A17: https://www.gem.wiki/PT_Kalimantan_Alumina_Nusantara_power_station | B17: PT Kalimantan Alumina Nusantara Unit 1 | C17: G100001093590 | D17: (new entry) | E17: Captive | F17: Aluminum | G17: 30 | I17: construction | M17: -0.1238386 | N17: 109.97131 | O17: Press Metal International Resources (HK) Ltd [80.0%]; PT Alakasa Alumina Refineri [17.2%]; small shareholder(s) [2.8%] | P17: West Kalimantan | Q17: Kalimantan Barat | R17: yes
A18: https://www.gem.wiki/PT_Kalimantan_Alumina_Nusantara_power_station | B18: PT Kalimantan Alumina Nusantara Unit 2 | C18: G100001093591 | D18: (new entry) | E18: Captive | F18: Aluminum | G18: 30 | I18: construction | M18: -0.1238386 | N18: 109.97131 | O18: Press Metal International Resources (HK) Ltd [80.0%]; PT Alakasa Alumina Refineri [17.2%]; small shareholder(s) [2.8%] | P18: West Kalimantan | Q18: Kalimantan Barat | R18: yes
A19: https://www.gem.wiki/Toba_Pulp_Lestari_power_station | B19: Toba Pulp Lestari Unit 2 | C19: G100001093598 | D19: (new entry) | E19: Captive | F19: Pulp and paper | G19: 30 | H19: 2014 | I19: mothballed | M19: 2.4636762 | N19: 99.197277 | O19: PT Toba Pulp Lestari Tbk [100.0%] | P19: North Sumatra | Q19: Sumatera Utara | R19: no
A20: https://www.gem.wiki/Perawang_Mill_power_station | B20: Perawang Mill Unit 05 | C20: G100001093579 | D20: (new entry) | E20: Captive | F20: Pulp and paper | G20: 35 | H20: 2008 | I20: operating | M20: 0.68932 | N20: 101.61907 | O20: PT Indah Kiat Pulp & Paper Tbk [100.0%] | P20: Riau | Q20: Riau | R20: no
A21: https://www.gem.wiki/Delong_Nickel_Phase_IV_power_station | B21: Delong Nickel Phase IV Unit 3 | C21: G100001031233 | D21: (new entry) | E21: Captive | F21: Nickel | G21: 330 | H21: 2024 | I21: operating | M21: -2.0165661 | N21: 121.43118 | O21: Zhongwei Hong Kong Zhengbang New Energy Co Ltd [35.0%]; Jiangsu Delong Nickel Industry Co Ltd [33.0%]; Zhongwei Hong Kong Zhenghong New Energy Co Ltd [25.0%]; Tongren Zhongwei Hongling No. 1 Enterprise Management Consulting Partnership LP [7.0%] | P21: Central Sulawesi | Q21: Sulawesi Tengah | R21: no
A22: https://www.gem.wiki/PT_Halmahera_Persada_Lygend_Nickel_Smelter_power_station | B22: PT Halmahera Persada Lygend Nickel Smelter Phase II Unit 5 | C22: G100001031294 | D22: (new entry) | E22: Captive | F22: Nickel | G22: 150 | H22: 2023 | I22: operating | M22: -1.5614331 | N22: 127.42103 | O22: Ningbo Lygend [36.9%]; Harita Group | P22: North Maluku | Q22: Maluku Utara | R22: no
A23: https://www.gem.wiki/PT_Krakatau_Posco_Energy_power_station | B23: PT Krakatau Posco Energy Unit 1 | C23: G100001093557 | D23: (new entry) | E23: Captive | F23: Chemicals, Iron & steel | G23: 100 | H23: 2014 | I23: operating | M23: -6.0068473 | N23: 105.97151 | O23: POSCO International Corp [55.0%]; PT Krakatau Chandra Energi [45.0%] | P23: Banten | Q23: Banten | R23: no
A24: https://www.gem.wiki/PT_Krakatau_Posco_Energy_power_station | B24: PT Krakatau Posco Energy Unit 2 | C24: G100001093558 | D24: (new entry) | E24: Captive | F24: Chemicals, Iron & steel | G24: 100 | H24: 2014 | I24: operating | M24: -6.0068473 | N24: 105.97151 | O24: POSCO International Corp [55.0%]; PT Krakatau Chandra Energi [45.0%] | P24: Banten | Q24: Banten | R24: no
A25: https://www.gem.wiki/Pindo-Deli-Ii_power_station | B25: Pindo-Deli-Ii Unit 3 | C25: G100001093577 | D25: (new entry) | E25: Captive | F25: Pulp and paper | G25: 30.2 | H25: 2007 | I25: operating | M25: -6.385474 | N25: 107.34362 | O25: PT APP Purinusa Ekapersada [99.2%]; small shareholder(s) [0.8%] | P25: West Java | Q25: Jawa Barat | R25: no
A26: https://www.gem.wiki/Pindo-Deli-Ii_power_station | B26: Pindo-Deli-Ii Unit 4 | C26: G100001093578 | D26: (new entry) | E26: Captive | F26: Pulp and paper | G26: 30.2 | H26: 2007 | I26: operating | M26: -6.385474 | N26: 107.34362 | O26: PT APP Purinusa Ekapersada [99.2%]; small shareholder(s) [0.8%] | P26: West Java | Q26: Jawa Barat | R26: no
A27: https://www.gem.wiki/South_Pasific_Viscose_power_station | B27: South Pasific Viscose -- | C27: G100001093582 | D27: (new entry) | E27: Captive | F27: Textile | G27: 30 | H27: 2009 | I27: operating | M27: -6.4981713 | N27: 107.39956 | O27: Lenzing AG [99.9%] | P27: West Java | Q27: Jawa Barat | R27: no
A28: https://www.gem.wiki/Toba_Pulp_Lestari_power_station | B28: Toba Pulp Lestari Unit 1 | C28: G100001093597 | D28: (new entry) | E28: Captive | F28: Pulp and paper | G28: 50 | H28: 2014 | I28: operating | M28: 2.4636762 | N28: 99.197277 | O28: PT Toba Pulp Lestari Tbk [100.0%] | P28: North Sumatra | Q28: Sumatera Utara | R28: no
A29: https://www.gem.wiki/Ketapang_Bangun_Sarana_power_station | B29: Ketapang Bangun Sarana Unit 1 | C29: G100001090979 | D29: (new entry) | E29: Captive | F29: Aluminum | G29: 45 | H29: 2025 | I29: operating | M29: -2.2356003 | N29: 110.10663 | O29: natural person(s) [46.6%]; Zhejiang Hengjia Holding Co Ltd [27.0%]; Hangzhou Yande Industrial Co Ltd [26.3%] | P29: West Kalimantan | Q29: Kalimantan Barat | R29: yes
A30: https://www.gem.wiki/Ketapang_Bangun_Sarana_power_station | B30: Ketapang Bangun Sarana Unit 2 | C30: G100001090980 | D30: (new entry) | E30: Captive | F30: Aluminum | G30: 30 | H30: 2025 | I30: operating | M30: -2.2356003 | N30: 110.10663 | O30: natural person(s) [46.6%]; Zhejiang Hengjia Holding Co Ltd [27.0%]; Hangzhou Yande Industrial Co Ltd [26.3%] | P30: West Kalimantan | Q30: Kalimantan Barat | R30: yes
A31: https://www.gem.wiki/Gallant_Venture_power_station | B31: Gallant Venture Phase II Unit 1 | C31: G100001054772 | D31: (new entry) | E31: Captive | F31: Industrial park | G31: 600 | I31: pre-permit | M31: 0.9575588 | N31: 104.04864 | O31: Gallant Venture Ltd [100.0%] | P31: Riau Islands | Q31: Kepulauan Riau | R31: yes
A32: https://www.gem.wiki/Gallant_Venture_power_station | B32: Gallant Venture Phase II Unit 2 | C32: G100001054773 | D32: (new entry) | E32: Captive | F32: Industrial park | G32: 600 | I32: pre-permit | M32: 0.9575588 | N32: 104.04864 | O32: Gallant Venture Ltd [100.0%] | P32: Riau Islands | Q32: Kepulauan Riau | R32: yes
A33: https://www.gem.wiki/East_Halmahera_power_station | B33: East Halmahera | C33: G100001090880 | D33: (new entry) | E33: Captive | F33: Nickel | G33: 680 | H33: 2028 | I33: pre-permit | M33: 0.84457743 | N33: 128.24938 | O33: PT Petrindo Jaya Kreasi Tbk [90.0%]; unknown [10.0%] | P33: North Maluku | Q33: Maluku Utara | R33: yes
A34: https://www.gem.wiki/Sulawesi_Labota_power_station | B34: Sulawesi Labota Unit 12 | C34: G100001093523 | D34: (new entry) | E34: Captive | F34: Aluminum, nickel | G34: 380 | I34: pre-permit | M34: -2.87427 | N34: 122.1777 | O34: Huafon Group Co Ltd [65.0%]; Eternal Tsingshan Group Ltd [35.0%] | P34: Central Sulawesi | Q34: Sulawesi Tengah | R34: yes
A35: https://www.gem.wiki/Wanxiang_Nickel_Indonesia_power_station | B35: Wanxiang Nickel Indonesia Phase II Unit 1 | C35: G100001093528 | D35: (new entry) | E35: Captive | F35: Nickel | G35: 200 | I35: pre-permit | M35: -2.730952 | N35: 122.03062 | O35: PT Wanxiang Steel Indonesia [100.0%] | P35: Central Sulawesi | Q35: Sulawesi Tengah | R35: yes
A36: https://www.gem.wiki/Wanxiang_Nickel_Indonesia_power_station | B36: Wanxiang Nickel Indonesia Phase II Unit 2 | C36: G100001093529 | D36: (new entry) | E36: Captive | F36: Nickel | G36: 200 | I36: pre-permit | M36: -2.730952 | N36: 122.03062 | O36: PT Wanxiang Steel Indonesia [100.0%] | P36: Central Sulawesi | Q36: Sulawesi Tengah | R36: yes
A37: https://www.gem.wiki/Tanjung_Sauh_power_station | B37: Tanjung Sauh Unit 1 | C37: G100001093559 | D37: (new entry) | E37: Captive | F37: Industrial park | G37: 150 | H37: 2026 | I37: pre-permit | M37: 1.0614475 | N37: 104.17374 | O37: PT Nusatama Properta Panbil | P37: Riau Islands | Q37: Kepulauan Riau | R37: yes
A38: https://www.gem.wiki/Tanjung_Sauh_power_station | B38: Tanjung Sauh Unit 2 | C38: G100001093560 | D38: (new entry) | E38: Captive | F38: Industrial park | G38: 150 | H38: 2027 | I38: pre-permit | M38: 1.0614475 | N38: 104.17374 | O38: PT Nusatama Properta Panbil | P38: Riau Islands | Q38: Kepulauan Riau | R38: yes
A39: https://www.gem.wiki/Mempawah_SGAR_power_station | B39: Mempawah SGAR Unit 1 | C39: G100001094663 | D39: (new entry) | E39: Captive | F39: Aluminum | G39: 200 | H39: 2028 | I39: pre-permit | M39: 0.36455793 | N39: 108.95568 | O39: PT Bukit Asam Tbk [100.0%] | P39: West Kalimantan | Q39: Kalimantan Barat | R39: yes
A40: https://www.gem.wiki/Mempawah_SGAR_power_station | B40: Mempawah SGAR Unit 2 | C40: G100001094664 | D40: (new entry) | E40: Captive | F40: Aluminum | G40: 200 | H40: 2028 | I40: pre-permit | M40: 0.36455793 | N40: 108.95568 | O40: PT Bukit Asam Tbk [100.0%] | P40: West Kalimantan | Q40: Kalimantan Barat | R40: yes
...

Sheet <30 MW_captive
A1: Plant name | B1: Unit name | C1: Capacity (MW) | D1: Status | E1: Fuel | F1: Owner | G1: Start year | H1: Captive | I1: Subnational unit (province, state) | J1: Coordinates | K1: Location accuracy | L1: Source link(s)
A2: Lati power station | B2: Unit 1 | C2: 7 | D2: Operating | E2: Coal | F2: PT Indo Pusaka Berau | G2: 2004 | H2: Mining | I2: East Kalimantan | J2: 2.2146149973028324, 117.6189402665326 | K2: Exact | L2: https://ipb.co.id/sekilas-indo-pusaka-berau/
A3: Lati power station | B3: Unit 2 | C3: 7 | D3: Operating | E3: Coal | F3: PT Indo Pusaka Berau | G3: 2004 | H3: Mining | I3: East Kalimantan | J3: 2.2146149973028324, 117.6189402665326 | K3: Exact | L3: https://ipb.co.id/sekilas-indo-pusaka-berau/
A4: Lati power station | B4: Unit 3 | C4: 7 | D4: Operating | E4: Coal | F4: PT Indo Pusaka Berau | G4: 2004 | H4: Mining | I4: East Kalimantan | J4: 2.2146149973028324, 117.6189402665326 | K4: Exact | L4: https://ipb.co.id/sekilas-indo-pusaka-berau/
